Workbook

Sheet Peugeot
A2: MES
A3: JUNIO | C3: =" "&"ACCIONES COMERCIALES B2B RED"&" - "&A3&" 2026" -> ACCIONES COMERCIALES B2B RED - JUNIO 2026
C6: TABLA DESCUENTOS FLOTAS | F6: Conces. Professional | H6: Conces. No Professional
F7: Tramo 1 (1 a 5) | G7: Tramo 2 (6 a 99) | H7: Tramo 1 (1 a 5) | I7: Tramo 2 (6 a 99) | K7: Grandes Cuentas (sobre 100) | N7: ∆ M-1 Tramo 1 (pp) | O7: ∆ M-1 Tramo 2 (pp) | P7: ∆ M-1 GC (pp)
C8: Versión | D8: Margen Fijo | E8: Aportes
A9: PARTNER MCA L1 BLUEHDI 100 | C9: PARTNER MCA L1 BLUEHDI 100 | D9: =VLOOKUP(A9,[1]Gestión!$D:$H,5,FALSE) -> 0.1 | E9: Total | F9: =+VLOOKUP(A9,'[1]B2B Red'!$C:$FG,MATCH($A$3,'[1]B2B Red'!$BG$6:$CU$6,0)+56,0) -> 0.1 | G9: =+VLOOKUP(A9,'[1]B2B Red'!$C:$FG,MATCH($A$3,'[1]B2B Red'!$BG$6:$CU$6,0)+57,0) -> 0.14 | H9: =+F9 -> 0.1 | I9: =+G9 -> 0.14 | K9: =+VLOOKUP(A9,'[1]B2B Red'!$C:$FG,MATCH($A$3,'[1]B2B Red'!$BG$6:$CU$6,0)+58,0)+4% -> 0.22 | N9: =IF((F9-VLOOKUP($A9,[2]Peugeot!$A:$L,COLUMNS([2]Peugeot!$A$9:$F$9),0))*100=0,"ISO",(F9-VLOOKUP($A9,[2]Peugeot!$A:$L,COLUMNS([2]Peugeot!$A$9:$F$9),0))*100) -> ISO | O9: =IF((G9-VLOOKUP($A9,[2]Peugeot!$A:$L,COLUMNS([2]Peugeot!$A$9:$G$9),0))*100=0,"ISO",(G9-VLOOKUP($A9,[2]Peugeot!$A:$L,COLUMNS([2]Peugeot!$A$9:$G$9),0))*100) -> ISO | P9: =IF((K9-VLOOKUP($A9,[2]Peugeot!$A:$L,COLUMNS([2]Peugeot!$A$9:$K$9),0))*100=0,"ISO",(K9-VLOOKUP($A9,[2]Peugeot!$A:$L,COLUMNS([2]Peugeot!$A$9:$K$9),0))*100) -> ISO
E10: Stellantis | F10: =+F9-F11 -> 0.055 | G10: =+G9-G11 -> 0.09 | H10: =+H9-H11 -> 0.045 | I10: =+I9-I11 -> 0.08 | K10: =+K9-K11 -> 0.15 | N10: =+IF((ROUND(F10-HLOOKUP(F$7,[2]Peugeot!$F$7:$G$86,MATCH($A9,[2]Peugeot!$A$7:$A$86,0)+1,0),3))*100=0,"ISO",(F10-HLOOKUP(F$7,[2]Peugeot!$F$7:$G$86,MATCH($A9,[2]Peugeot!$A$7:$A$86,0)+1,0))*100) -> ISO | O10: =+IF((ROUND(G10-HLOOKUP(G$7,[2]Peugeot!$F$7:$G$86,MATCH($A9,[2]Peugeot!$A$7:$A$86,0)+1,0),3))*100=0,"ISO",(G10-HLOOKUP(G$7,[2]Peugeot!$F$7:$G$86,MATCH($A9,[2]Peugeot!$A$7:$A$86,0)+1,0))*100) -> ISO | P10: =IF((ROUND(K10-HLOOKUP(K$7,[2]Peugeot!$K$7:$L$86,MATCH($A9,[2]Peugeot!$A$7:$A$86,0)+1,0),3))*100=0,"ISO",(K10-HLOOKUP(K$7,[2]Peugeot!$K$7:$L$86,MATCH($A9,[2]Peugeot!$A$7:$A$86,0)+1,0))*100) -> ISO
E11: RED | F11: =+D9-VLOOKUP(A9,'[1]B2B Red'!$C:$FG,MATCH($A$3,'[1]B2B Red'!$CV$6:$EE$6,0)+97,0) -> 0.045 | G11: =+D9-VLOOKUP(A9,'[1]B2B Red'!$C:$FG,MATCH($A$3,'[1]B2B Red'!$CV$6:$EE$6,0)+98,0) -> 0.05 | H11: =+F11+1% -> 0.055 | I11: =+G11+1% -> 0.06 | K11: =+D9-VLOOKUP(A9,'[1]B2B Red'!$C:$FG,MATCH($A$3,'[1]B2B Red'!$CV$6:$EE$6,0)+99,0)+1% -> 0.07 | N11: =+IF((ROUND(F11-HLOOKUP(F$7,[2]Peugeot!$F$7:$G$86,MATCH($A9,[2]Peugeot!$A$7:$A$86,0)+2,0),3))*100=0,"ISO",(F11-HLOOKUP(F$7,[2]Peugeot!$F$7:$G$86,MATCH($A9,[2]Peugeot!$A$7:$A$86,0)+2,0))*100) -> ISO | O11: =IF((ROUND(G11-HLOOKUP(G$7,[2]Peugeot!$F$7:$G$86,MATCH($A9,[2]Peugeot!$A$7:$A$86,0)+2,0),3))*100=0,"ISO",(G11-HLOOKUP(G$7,[2]Peugeot!$F$7:$G$86,MATCH($A9,[2]Peugeot!$A$7:$A$86,0)+2,0))*100) -> ISO | P11: =IF((ROUND(K11-HLOOKUP(K$7,[2]Peugeot!$K$7:$L$86,MATCH($A9,[2]Peugeot!$A$7:$A$86,0)+2,0),3))*100=0,"ISO",(K11-HLOOKUP(K$7,[2]Peugeot!$K$7:$L$86,MATCH($A9,[2]Peugeot!$A$7:$A$86,0)+2,0))*100) -> ISO
A13: PARTNER MCA L2 BLUEHDI 100 | C13: PARTNER MCA L2 DIESEL 100HP MT | D13: =VLOOKUP(A13,[1]Gestión!$D:$H,5,FALSE) -> 0.1 | E13: Total | F13: =+VLOOKUP(A13,'[1]B2B Red'!$C:$FG,MATCH($A$3,'[1]B2B Red'!$BG$6:$CU$6,0)+56,0) -> 0.1 | G13: =+VLOOKUP(A13,'[1]B2B Red'!$C:$FG,MATCH($A$3,'[1]B2B Red'!$BG$6:$CU$6,0)+57,0) -> 0.14 | H13: =+F13 -> 0.1 | I13: =+G13 -> 0.14 | K13: =+VLOOKUP(A13,'[1]B2B Red'!$C:$FG,MATCH($A$3,'[1]B2B Red'!$BG$6:$CU$6,0)+58,0)+4% -> 0.22 | N13: =IF((F13-VLOOKUP($A13,[2]Peugeot!$A:$L,COLUMNS([2]Peugeot!$A$9:$F$9),0))*100=0,"ISO",(F13-VLOOKUP($A13,[2]Peugeot!$A:$L,COLUMNS([2]Peugeot!$A$9:$F$9),0))*100) -> ISO | O13: =IF((G13-VLOOKUP($A13,[2]Peugeot!$A:$L,COLUMNS([2]Peugeot!$A$9:$G$9),0))*100=0,"ISO",(G13-VLOOKUP($A13,[2]Peugeot!$A:$L,COLUMNS([2]Peugeot!$A$9:$G$9),0))*100) -> ISO | P13: =IF((K13-VLOOKUP($A13,[2]Peugeot!$A:$L,COLUMNS([2]Peugeot!$A$9:$K$9),0))*100=0,"ISO",(K13-VLOOKUP($A13,[2]Peugeot!$A:$L,COLUMNS([2]Peugeot!$A$9:$K$9),0))*100) -> ISO
E14: Stellantis | F14: =+F13-F15 -> 0.055 | G14: =+G13-G15 -> 0.09 | H14: =+H13-H15 -> 0.045 | I14: =+I13-I15 -> 0.08 | K14: =+K13-K15 -> 0.15 | N14: =+IF((ROUND(F14-HLOOKUP(F$7,[2]Peugeot!$F$7:$G$86,MATCH($A13,[2]Peugeot!$A$7:$A$86,0)+1,0),3))*100=0,"ISO",(F14-HLOOKUP(F$7,[2]Peugeot!$F$7:$G$86,MATCH($A13,[2]Peugeot!$A$7:$A$86,0)+1,0))*100) -> ISO | O14: =+IF((ROUND(G14-HLOOKUP(G$7,[2]Peugeot!$F$7:$G$86,MATCH($A13,[2]Peugeot!$A$7:$A$86,0)+1,0),3))*100=0,"ISO",(G14-HLOOKUP(G$7,[2]Peugeot!$F$7:$G$86,MATCH($A13,[2]Peugeot!$A$7:$A$86,0)+1,0))*100) -> ISO | P14: =IF((ROUND(K14-HLOOKUP(K$7,[2]Peugeot!$K$7:$L$86,MATCH($A13,[2]Peugeot!$A$7:$A$86,0)+1,0),3))*100=0,"ISO",(K14-HLOOKUP(K$7,[2]Peugeot!$K$7:$L$86,MATCH($A13,[2]Peugeot!$A$7:$A$86,0)+1,0))*100) -> ISO
E15: RED | F15: =+D13-VLOOKUP(A13,'[1]B2B Red'!$C:$FG,MATCH($A$3,'[1]B2B Red'!$CV$6:$EE$6,0)+97,0) -> 0.045 | G15: =+D13-VLOOKUP(A13,'[1]B2B Red'!$C:$FG,MATCH($A$3,'[1]B2B Red'!$CV$6:$EE$6,0)+98,0) -> 0.05 | H15: =+F15+1% -> 0.055 | I15: =+G15+1% -> 0.06 | K15: =+D13-VLOOKUP(A13,'[1]B2B Red'!$C:$FG,MATCH($A$3,'[1]B2B Red'!$CV$6:$EE$6,0)+99,0)+1% -> 0.07 | N15: =+IF((ROUND(F15-HLOOKUP(F$7,[2]Peugeot!$F$7:$G$86,MATCH($A13,[2]Peugeot!$A$7:$A$86,0)+2,0),3))*100=0,"ISO",(F15-HLOOKUP(F$7,[2]Peugeot!$F$7:$G$86,MATCH($A13,[2]Peugeot!$A$7:$A$86,0)+2,0))*100) -> ISO | O15: =IF((ROUND(G15-HLOOKUP(G$7,[2]Peugeot!$F$7:$G$86,MATCH($A13,[2]Peugeot!$A$7:$A$86,0)+2,0),3))*100=0,"ISO",(G15-HLOOKUP(G$7,[2]Peugeot!$F$7:$G$86,MATCH($A13,[2]Peugeot!$A$7:$A$86,0)+2,0))*100) -> ISO | P15: =IF((ROUND(K15-HLOOKUP(K$7,[2]Peugeot!$K$7:$L$86,MATCH($A13,[2]Peugeot!$A$7:$A$86,0)+2,0),3))*100=0,"ISO",(K15-HLOOKUP(K$7,[2]Peugeot!$K$7:$L$86,MATCH($A13,[2]Peugeot!$A$7:$A$86,0)+2,0))*100) -> ISO
A17: Expert MCA L3 BlueHdi 145 | C17: EXPERT MCA L3 DIESEL 145HP MT | D17: =VLOOKUP(A17,[1]Gestión!$D:$H,5,FALSE) -> 0.1 | E17: Total | F17: =+VLOOKUP(A17,'[1]B2B Red'!$C:$FG,MATCH($A$3,'[1]B2B Red'!$BG$6:$CU$6,0)+56,0) -> 0.14 | G17: =+VLOOKUP(A17,'[1]B2B Red'!$C:$FG,MATCH($A$3,'[1]B2B Red'!$BG$6:$CU$6,0)+57,0) -> 0.14 | H17: =+F17 -> 0.14 | I17: =+G17 -> 0.14 | K17: =+VLOOKUP(A17,'[1]B2B Red'!$C:$FG,MATCH($A$3,'[1]B2B Red'!$BG$6:$CU$6,0)+58,0) -> 0.16 | N17: =IF((F17-VLOOKUP($A17,[2]Peugeot!$A:$L,COLUMNS([2]Peugeot!$A$9:$F$9),0))*100=0,"ISO",(F17-VLOOKUP($A17,[2]Peugeot!$A:$L,COLUMNS([2]Peugeot!$A$9:$F$9),0))*100) -> ISO | O17: =IF((G17-VLOOKUP($A17,[2]Peugeot!$A:$L,COLUMNS([2]Peugeot!$A$9:$G$9),0))*100=0,"ISO",(G17-VLOOKUP($A17,[2]Peugeot!$A:$L,COLUMNS([2]Peugeot!$A$9:$G$9),0))*100) -> ISO | P17: =IF((K17-VLOOKUP($A17,[2]Peugeot!$A:$L,COLUMNS([2]Peugeot!$A$9:$K$9),0))*100=0,"ISO",(K17-VLOOKUP($A17,[2]Peugeot!$A:$L,COLUMNS([2]Peugeot!$A$9:$K$9),0))*100) -> ISO
E18: Stellantis | F18: =+F17-F19 -> 0.09 | G18: =+G17-G19 -> 0.09 | H18: =+H17-H19 -> 0.08 | I18: =+I17-I19 -> 0.08 | K18: =+K17-K19 -> 0.1 | N18: =+IF((ROUND(F18-HLOOKUP(F$7,[2]Peugeot!$F$7:$G$86,MATCH($A17,[2]Peugeot!$A$7:$A$86,0)+1,0),3))*100=0,"ISO",(F18-HLOOKUP(F$7,[2]Peugeot!$F$7:$G$86,MATCH($A17,[2]Peugeot!$A$7:$A$86,0)+1,0))*100) -> ISO | O18: =+IF((ROUND(G18-HLOOKUP(G$7,[2]Peugeot!$F$7:$G$86,MATCH($A17,[2]Peugeot!$A$7:$A$86,0)+1,0),3))*100=0,"ISO",(G18-HLOOKUP(G$7,[2]Peugeot!$F$7:$G$86,MATCH($A17,[2]Peugeot!$A$7:$A$86,0)+1,0))*100) -> ISO | P18: =IF((ROUND(K18-HLOOKUP(K$7,[2]Peugeot!$K$7:$L$86,MATCH($A17,[2]Peugeot!$A$7:$A$86,0)+1,0),3))*100=0,"ISO",(K18-HLOOKUP(K$7,[2]Peugeot!$K$7:$L$86,MATCH($A17,[2]Peugeot!$A$7:$A$86,0)+1,0))*100) -> ISO
E19: RED | F19: =+D17-VLOOKUP(A17,'[1]B2B Red'!$C:$FG,MATCH($A$3,'[1]B2B Red'!$CV$6:$EE$6,0)+97,0) -> 0.05 | G19: =+D17-VLOOKUP(A17,'[1]B2B Red'!$C:$FG,MATCH($A$3,'[1]B2B Red'!$CV$6:$EE$6,0)+98,0) -> 0.05 | H19: =+F19+1% -> 0.06 | I19: =+G19+1% -> 0.06 | K19: =+D17-VLOOKUP(A17,'[1]B2B Red'!$C:$FG,MATCH($A$3,'[1]B2B Red'!$CV$6:$EE$6,0)+99,0) -> 0.06 | N19: =+IF((ROUND(F19-HLOOKUP(F$7,[2]Peugeot!$F$7:$G$86,MATCH($A17,[2]Peugeot!$A$7:$A$86,0)+2,0),3))*100=0,"ISO",(F19-HLOOKUP(F$7,[2]Peugeot!$F$7:$G$86,MATCH($A17,[2]Peugeot!$A$7:$A$86,0)+2,0))*100) -> ISO | O19: =IF((ROUND(G19-HLOOKUP(G$7,[2]Peugeot!$F$7:$G$86,MATCH($A17,[2]Peugeot!$A$7:$A$86,0)+2,0),3))*100=0,"ISO",(G19-HLOOKUP(G$7,[2]Peugeot!$F$7:$G$86,MATCH($A17,[2]Peugeot!$A$7:$A$86,0)+2,0))*100) -> ISO | P19: =IF((ROUND(K19-HLOOKUP(K$7,[2]Peugeot!$K$7:$L$86,MATCH($A17,[2]Peugeot!$A$7:$A$86,0)+2,0),3))*100=0,"ISO",(K19-HLOOKUP(K$7,[2]Peugeot!$K$7:$L$86,MATCH($A17,[2]Peugeot!$A$7:$A$86,0)+2,0))*100) -> ISO
A20: Traveller MCA Business L3 8P BlueHDi 180 EAT8 | C20: Familia TRAVELLER | D20: =VLOOKUP(A20,[1]Gestión!$D:$H,5,FALSE) -> 0.1 | E20: Total | F20: =+VLOOKUP(A20,'[1]B2B Red'!$C:$FG,MATCH($A$3,'[1]B2B Red'!$BG$6:$CU$6,0)+56,0) -> 0.12 | G20: =+VLOOKUP(A20,'[1]B2B Red'!$C:$FG,MATCH($A$3,'[1]B2B Red'!$BG$6:$CU$6,0)+57,0) -> 0.12 | H20: =+F20 -> 0.12 | I20: =+G20 -> 0.12 | K20: =+VLOOKUP(A20,'[1]B2B Red'!$C:$FG,MATCH($A$3,'[1]B2B Red'!$BG$6:$CU$6,0)+58,0) -> 0.14 | N20: =IF((F20-VLOOKUP($A20,[2]Peugeot!$A:$L,COLUMNS([2]Peugeot!$A$9:$F$9),0))*100=0,"ISO",(F20-VLOOKUP($A20,[2]Peugeot!$A:$L,COLUMNS([2]Peugeot!$A$9:$F$9),0))*100) -> -2 | O20: =IF((G20-VLOOKUP($A20,[2]Peugeot!$A:$L,COLUMNS([2]Peugeot!$A$9:$G$9),0))*100=0,"ISO",(G20-VLOOKUP($A20,[2]Peugeot!$A:$L,COLUMNS([2]Peugeot!$A$9:$G$9),0))*100) -> -2 | P20: =IF((K20-VLOOKUP($A20,[2]Peugeot!$A:$L,COLUMNS([2]Peugeot!$A$9:$K$9),0))*100=0,"ISO",(K20-VLOOKUP($A20,[2]Peugeot!$A:$L,COLUMNS([2]Peugeot!$A$9:$K$9),0))*100) -> -2
E21: Stellantis | F21: =+F20-F22 -> 0.07 | G21: =+G20-G22 -> 0.07 | H21: =+H20-H22 -> 0.06 | I21: =+I20-I22 -> 0.06 | K21: =+K20-K22 -> 0.08 | N21: =+IF((ROUND(F21-HLOOKUP(F$7,[2]Peugeot!$F$7:$G$86,MATCH($A20,[2]Peugeot!$A$7:$A$86,0)+1,0),3))*100=0,"ISO",(F21-HLOOKUP(F$7,[2]Peugeot!$F$7:$G$86,MATCH($A20,[2]Peugeot!$A$7:$A$86,0)+1,0))*100) -> -2 | O21: =+IF((ROUND(G21-HLOOKUP(G$7,[2]Peugeot!$F$7:$G$86,MATCH($A20,[2]Peugeot!$A$7:$A$86,0)+1,0),3))*100=0,"ISO",(G21-HLOOKUP(G$7,[2]Peugeot!$F$7:$G$86,MATCH($A20,[2]Peugeot!$A$7:$A$86,0)+1,0))*100) -> -2 | P21: =IF((ROUND(K21-HLOOKUP(K$7,[2]Peugeot!$K$7:$L$86,MATCH($A20,[2]Peugeot!$A$7:$A$86,0)+1,0),3))*100=0,"ISO",(K21-HLOOKUP(K$7,[2]Peugeot!$K$7:$L$86,MATCH($A20,[2]Peugeot!$A$7:$A$86,0)+1,0))*100) -> -2
E22: RED | F22: =+D20-VLOOKUP(A20,'[1]B2B Red'!$C:$FG,MATCH($A$3,'[1]B2B Red'!$CV$6:$EE$6,0)+97,0) -> 0.05 | G22: =+D20-VLOOKUP(A20,'[1]B2B Red'!$C:$FG,MATCH($A$3,'[1]B2B Red'!$CV$6:$EE$6,0)+98,0) -> 0.05 | H22: =+F22+1% -> 0.06 | I22: =+G22+1% -> 0.06 | K22: =+D20-VLOOKUP(A20,'[1]B2B Red'!$C:$FG,MATCH($A$3,'[1]B2B Red'!$CV$6:$EE$6,0)+99,0) -> 0.06 | N22: =+IF((ROUND(F22-HLOOKUP(F$7,[2]Peugeot!$F$7:$G$86,MATCH($A20,[2]Peugeot!$A$7:$A$86,0)+2,0),3))*100=0,"ISO",(F22-HLOOKUP(F$7,[2]Peugeot!$F$7:$G$86,MATCH($A20,[2]Peugeot!$A$7:$A$86,0)+2,0))*100) -> ISO | O22: =IF((ROUND(G22-HLOOKUP(G$7,[2]Peugeot!$F$7:$G$86,MATCH($A20,[2]Peugeot!$A$7:$A$86,0)+2,0),3))*100=0,"ISO",(G22-HLOOKUP(G$7,[2]Peugeot!$F$7:$G$86,MATCH($A20,[2]Peugeot!$A$7:$A$86,0)+2,0))*100) -> ISO | P22: =IF((ROUND(K22-HLOOKUP(K$7,[2]Peugeot!$K$7:$L$86,MATCH($A20,[2]Peugeot!$A$7:$A$86,0)+2,0),3))*100=0,"ISO",(K22-HLOOKUP(K$7,[2]Peugeot!$K$7:$L$86,MATCH($A20,[2]Peugeot!$A$7:$A$86,0)+2,0))*100) -> ISO
A24: Boxer MCA Furgón L2H2 BlueHDi | C24: BOXER MCA Furgón L2H2 Diesel 140hp MT | D24: =VLOOKUP(A24,[1]Gestión!$D:$H,5,FALSE) -> 0.1 | E24: Total | F24: =+VLOOKUP(A24,'[1]B2B Red'!$C:$FG,MATCH($A$3,'[1]B2B Red'!$BG$6:$CU$6,0)+56,0) -> 0.15 | G24: =+VLOOKUP(A24,'[1]B2B Red'!$C:$FG,MATCH($A$3,'[1]B2B Red'!$BG$6:$CU$6,0)+57,0) -> 0.17 | H24: =+F24 -> 0.15 | I24: =+G24 -> 0.17 | K24: =+VLOOKUP(A24,'[1]B2B Red'!$C:$FG,MATCH($A$3,'[1]B2B Red'!$BG$6:$CU$6,0)+58,0) -> 0.21 | N24: =IF((F24-VLOOKUP($A24,[2]Peugeot!$A:$L,COLUMNS([2]Peugeot!$A$9:$F$9),0))*100=0,"ISO",(F24-VLOOKUP($A24,[2]Peugeot!$A:$L,COLUMNS([2]Peugeot!$A$9:$F$9),0))*100) -> 1 | O24: =IF((G24-VLOOKUP($A24,[2]Peugeot!$A:$L,COLUMNS([2]Peugeot!$A$9:$G$9),0))*100=0,"ISO",(G24-VLOOKUP($A24,[2]Peugeot!$A:$L,COLUMNS([2]Peugeot!$A$9:$G$9),0))*100) -> 1 | P24: =IF((K24-VLOOKUP($A24,[2]Peugeot!$A:$L,COLUMNS([2]Peugeot!$A$9:$K$9),0))*100=0,"ISO",(K24-VLOOKUP($A24,[2]Peugeot!$A:$L,COLUMNS([2]Peugeot!$A$9:$K$9),0))*100) -> 1
E25: Stellantis | F25: =+F24-F26 -> 0.11 | G25: =+G24-G26 -> 0.12 | H25: =+H24-H26 -> 0.1 | I25: =+I24-I26 -> 0.11 | K25: =+K24-K26 -> 0.145 | N25: =+IF((ROUND(F25-HLOOKUP(F$7,[2]Peugeot!$F$7:$G$86,MATCH($A24,[2]Peugeot!$A$7:$A$86,0)+1,0),3))*100=0,"ISO",(F25-HLOOKUP(F$7,[2]Peugeot!$F$7:$G$86,MATCH($A24,[2]Peugeot!$A$7:$A$86,0)+1,0))*100) -> 1 | O25: =+IF((ROUND(G25-HLOOKUP(G$7,[2]Peugeot!$F$7:$G$86,MATCH($A24,[2]Peugeot!$A$7:$A$86,0)+1,0),3))*100=0,"ISO",(G25-HLOOKUP(G$7,[2]Peugeot!$F$7:$G$86,MATCH($A24,[2]Peugeot!$A$7:$A$86,0)+1,0))*100) -> 1 | P25: =IF((ROUND(K25-HLOOKUP(K$7,[2]Peugeot!$K$7:$L$86,MATCH($A24,[2]Peugeot!$A$7:$A$86,0)+1,0),3))*100=0,"ISO",(K25-HLOOKUP(K$7,[2]Peugeot!$K$7:$L$86,MATCH($A24,[2]Peugeot!$A$7:$A$86,0)+1,0))*100) -> 1
E26: RED | F26: =+D24-VLOOKUP(A24,'[1]B2B Red'!$C:$FG,MATCH($A$3,'[1]B2B Red'!$CV$6:$EE$6,0)+97,0) -> 0.04 | G26: =+D24-VLOOKUP(A24,'[1]B2B Red'!$C:$FG,MATCH($A$3,'[1]B2B Red'!$CV$6:$EE$6,0)+98,0) -> 0.05 | H26: =+F26+1% -> 0.05 | I26: =+G26+1% -> 0.06 | K26: =+D24-VLOOKUP(A24,'[1]B2B Red'!$C:$FG,MATCH($A$3,'[1]B2B Red'!$CV$6:$EE$6,0)+99,0) -> 0.065 | N26: =+IF((ROUND(F26-HLOOKUP(F$7,[2]Peugeot!$F$7:$G$86,MATCH($A24,[2]Peugeot!$A$7:$A$86,0)+2,0),3))*100=0,"ISO",(F26-HLOOKUP(F$7,[2]Peugeot!$F$7:$G$86,MATCH($A24,[2]Peugeot!$A$7:$A$86,0)+2,0))*100) -> ISO | O26: =IF((ROUND(G26-HLOOKUP(G$7,[2]Peugeot!$F$7:$G$86,MATCH($A24,[2]Peugeot!$A$7:$A$86,0)+2,0),3))*100=0,"ISO",(G26-HLOOKUP(G$7,[2]Peugeot!$F$7:$G$86,MATCH($A24,[2]Peugeot!$A$7:$A$86,0)+2,0))*100) -> ISO | P26: =IF((ROUND(K26-HLOOKUP(K$7,[2]Peugeot!$K$7:$L$86,MATCH($A24,[2]Peugeot!$A$7:$A$86,0)+2,0),3))*100=0,"ISO",(K26-HLOOKUP(K$7,[2]Peugeot!$K$7:$L$86,MATCH($A24,[2]Peugeot!$A$7:$A$86,0)+2,0))*100) -> ISO
A27: Boxer MCA Furgón L3H2 BlueHDi | C27: BOXER MCA Furgón L3H2 Diesel 140hp MT | D27: =VLOOKUP(A27,[1]Gestión!$D:$H,5,FALSE) -> 0.1 | E27: Total | F27: =+VLOOKUP(A27,'[1]B2B Red'!$C:$FG,MATCH($A$3,'[1]B2B Red'!$BG$6:$CU$6,0)+56,0) -> 0.14 | G27: =+VLOOKUP(A27,'[1]B2B Red'!$C:$FG,MATCH($A$3,'[1]B2B Red'!$BG$6:$CU$6,0)+57,0) -> 0.16 | H27: =+F27 -> 0.14 | I27: =+G27 -> 0.16 | K27: =+VLOOKUP(A27,'[1]B2B Red'!$C:$FG,MATCH($A$3,'[1]B2B Red'!$BG$6:$CU$6,0)+58,0) -> 0.2 | N27: =IF((F27-VLOOKUP($A27,[2]Peugeot!$A:$L,COLUMNS([2]Peugeot!$A$9:$F$9),0))*100=0,"ISO",(F27-VLOOKUP($A27,[2]Peugeot!$A:$L,COLUMNS([2]Peugeot!$A$9:$F$9),0))*100) -> ISO | O27: =IF((G27-VLOOKUP($A27,[2]Peugeot!$A:$L,COLUMNS([2]Peugeot!$A$9:$G$9),0))*100=0,"ISO",(G27-VLOOKUP($A27,[2]Peugeot!$A:$L,COLUMNS([2]Peugeot!$A$9:$G$9),0))*100) -> ISO | P27: =IF((K27-VLOOKUP($A27,[2]Peugeot!$A:$L,COLUMNS([2]Peugeot!$A$9:$K$9),0))*100=0,"ISO",(K27-VLOOKUP($A27,[2]Peugeot!$A:$L,COLUMNS([2]Peugeot!$A$9:$K$9),0))*100) -> ISO
E28: Stellantis | F28: =+F27-F29 -> 0.1 | G28: =+G27-G29 -> 0.11 | H28: =+H27-H29 -> 0.09 | I28: =+I27-I29 -> 0.1 | K28: =+K27-K29 -> 0.135 | N28: =+IF((ROUND(F28-HLOOKUP(F$7,[2]Peugeot!$F$7:$G$86,MATCH($A27,[2]Peugeot!$A$7:$A$86,0)+1,0),3))*100=0,"ISO",(F28-HLOOKUP(F$7,[2]Peugeot!$F$7:$G$86,MATCH($A27,[2]Peugeot!$A$7:$A$86,0)+1,0))*100) -> ISO | O28: =+IF((ROUND(G28-HLOOKUP(G$7,[2]Peugeot!$F$7:$G$86,MATCH($A27,[2]Peugeot!$A$7:$A$86,0)+1,0),3))*100=0,"ISO",(G28-HLOOKUP(G$7,[2]Peugeot!$F$7:$G$86,MATCH($A27,[2]Peugeot!$A$7:$A$86,0)+1,0))*100) -> ISO | P28: =IF((ROUND(K28-HLOOKUP(K$7,[2]Peugeot!$K$7:$L$86,MATCH($A27,[2]Peugeot!$A$7:$A$86,0)+1,0),3))*100=0,"ISO",(K28-HLOOKUP(K$7,[2]Peugeot!$K$7:$L$86,MATCH($A27,[2]Peugeot!$A$7:$A$86,0)+1,0))*100) -> ISO
E29: RED | F29: =+D27-VLOOKUP(A27,'[1]B2B Red'!$C:$FG,MATCH($A$3,'[1]B2B Red'!$CV$6:$EE$6,0)+97,0) -> 0.04 | G29: =+D27-VLOOKUP(A27,'[1]B2B Red'!$C:$FG,MATCH($A$3,'[1]B2B Red'!$CV$6:$EE$6,0)+98,0) -> 0.05 | H29: =+F29+1% -> 0.05 | I29: =+G29+1% -> 0.06 | K29: =+D27-VLOOKUP(A27,'[1]B2B Red'!$C:$FG,MATCH($A$3,'[1]B2B Red'!$CV$6:$EE$6,0)+99,0) -> 0.065 | N29: =+IF((ROUND(F29-HLOOKUP(F$7,[2]Peugeot!$F$7:$G$86,MATCH($A27,[2]Peugeot!$A$7:$A$86,0)+2,0),3))*100=0,"ISO",(F29-HLOOKUP(F$7,[2]Peugeot!$F$7:$G$86,MATCH($A27,[2]Peugeot!$A$7:$A$86,0)+2,0))*100) -> ISO | O29: =IF((ROUND(G29-HLOOKUP(G$7,[2]Peugeot!$F$7:$G$86,MATCH($A27,[2]Peugeot!$A$7:$A$86,0)+2,0),3))*100=0,"ISO",(G29-HLOOKUP(G$7,[2]Peugeot!$F$7:$G$86,MATCH($A27,[2]Peugeot!$A$7:$A$86,0)+2,0))*100) -> ISO | P29: =IF((ROUND(K29-HLOOKUP(K$7,[2]Peugeot!$K$7:$L$86,MATCH($A27,[2]Peugeot!$A$7:$A$86,0)+2,0),3))*100=0,"ISO",(K29-HLOOKUP(K$7,[2]Peugeot!$K$7:$L$86,MATCH($A27,[2]Peugeot!$A$7:$A$86,0)+2,0))*100) -> ISO
A30: Boxer MCA Furgón L4H2 BlueHDi | C30: BOXER MCA Furgón L4H2 Diesel 140hp MT | D30: =VLOOKUP(A30,[1]Gestión!$D:$H,5,FALSE) -> 0.1 | E30: Total | F30: =+VLOOKUP(A30,'[1]B2B Red'!$C:$FG,MATCH($A$3,'[1]B2B Red'!$BG$6:$CU$6,0)+56,0) -> 0.14 | G30: =+VLOOKUP(A30,'[1]B2B Red'!$C:$FG,MATCH($A$3,'[1]B2B Red'!$BG$6:$CU$6,0)+57,0) -> 0.16 | H30: =+F30 -> 0.14 | I30: =+G30 -> 0.16 | K30: =+VLOOKUP(A30,'[1]B2B Red'!$C:$FG,MATCH($A$3,'[1]B2B Red'!$BG$6:$CU$6,0)+58,0) -> 0.2 | N30: =IF((F30-VLOOKUP($A30,[2]Peugeot!$A:$L,COLUMNS([2]Peugeot!$A$9:$F$9),0))*100=0,"ISO",(F30-VLOOKUP($A30,[2]Peugeot!$A:$L,COLUMNS([2]Peugeot!$A$9:$F$9),0))*100) -> ISO | O30: =IF((G30-VLOOKUP($A30,[2]Peugeot!$A:$L,COLUMNS([2]Peugeot!$A$9:$G$9),0))*100=0,"ISO",(G30-VLOOKUP($A30,[2]Peugeot!$A:$L,COLUMNS([2]Peugeot!$A$9:$G$9),0))*100) -> ISO | P30: =IF((K30-VLOOKUP($A30,[2]Peugeot!$A:$L,COLUMNS([2]Peugeot!$A$9:$K$9),0))*100=0,"ISO",(K30-VLOOKUP($A30,[2]Peugeot!$A:$L,COLUMNS([2]Peugeot!$A$9:$K$9),0))*100) -> ISO
E31: Stellantis | F31: =+F30-F32 -> 0.1 | G31: =+G30-G32 -> 0.11 | H31: =+H30-H32 -> 0.09 | I31: =+I30-I32 -> 0.1 | K31: =+K30-K32 -> 0.135 | N31: =+IF((ROUND(F31-HLOOKUP(F$7,[2]Peugeot!$F$7:$G$86,MATCH($A30,[2]Peugeot!$A$7:$A$86,0)+1,0),3))*100=0,"ISO",(F31-HLOOKUP(F$7,[2]Peugeot!$F$7:$G$86,MATCH($A30,[2]Peugeot!$A$7:$A$86,0)+1,0))*100) -> ISO | O31: =+IF((ROUND(G31-HLOOKUP(G$7,[2]Peugeot!$F$7:$G$86,MATCH($A30,[2]Peugeot!$A$7:$A$86,0)+1,0),3))*100=0,"ISO",(G31-HLOOKUP(G$7,[2]Peugeot!$F$7:$G$86,MATCH($A30,[2]Peugeot!$A$7:$A$86,0)+1,0))*100) -> ISO | P31: =IF((ROUND(K31-HLOOKUP(K$7,[2]Peugeot!$K$7:$L$86,MATCH($A30,[2]Peugeot!$A$7:$A$86,0)+1,0),3))*100=0,"ISO",(K31-HLOOKUP(K$7,[2]Peugeot!$K$7:$L$86,MATCH($A30,[2]Peugeot!$A$7:$A$86,0)+1,0))*100) -> ISO
E32: RED | F32: =+D30-VLOOKUP(A30,'[1]B2B Red'!$C:$FG,MATCH($A$3,'[1]B2B Red'!$CV$6:$EE$6,0)+97,0) -> 0.04 | G32: =+D30-VLOOKUP(A30,'[1]B2B Red'!$C:$FG,MATCH($A$3,'[1]B2B Red'!$CV$6:$EE$6,0)+98,0) -> 0.05 | H32: =+F32+1% -> 0.05 | I32: =+G32+1% -> 0.06 | K32: =+D30-VLOOKUP(A30,'[1]B2B Red'!$C:$FG,MATCH($A$3,'[1]B2B Red'!$CV$6:$EE$6,0)+99,0) -> 0.065 | N32: =+IF((ROUND(F32-HLOOKUP(F$7,[2]Peugeot!$F$7:$G$86,MATCH($A30,[2]Peugeot!$A$7:$A$86,0)+2,0),3))*100=0,"ISO",(F32-HLOOKUP(F$7,[2]Peugeot!$F$7:$G$86,MATCH($A30,[2]Peugeot!$A$7:$A$86,0)+2,0))*100) -> ISO | O32: =IF((ROUND(G32-HLOOKUP(G$7,[2]Peugeot!$F$7:$G$86,MATCH($A30,[2]Peugeot!$A$7:$A$86,0)+2,0),3))*100=0,"ISO",(G32-HLOOKUP(G$7,[2]Peugeot!$F$7:$G$86,MATCH($A30,[2]Peugeot!$A$7:$A$86,0)+2,0))*100) -> ISO | P32: =IF((ROUND(K32-HLOOKUP(K$7,[2]Peugeot!$K$7:$L$86,MATCH($A30,[2]Peugeot!$A$7:$A$86,0)+2,0),3))*100=0,"ISO",(K32-HLOOKUP(K$7,[2]Peugeot!$K$7:$L$86,MATCH($A30,[2]Peugeot!$A$7:$A$86,0)+2,0))*100) -> ISO
A34: Landtrek Action4 BlueHDi 4x4 AT 6.3 | C34: LANDTREK MCA | D34: =VLOOKUP(A34,[1]Gestión!$D:$H,5,FALSE) -> 0.1 | E34: Total | F34: =+VLOOKUP(A34,'[1]B2B Red'!$C:$FG,MATCH($A$3,'[1]B2B Red'!$BG$6:$CU$6,0)+56,0) -> 0.25 | G34: =+VLOOKUP(A34,'[1]B2B Red'!$C:$FG,MATCH($A$3,'[1]B2B Red'!$BG$6:$CU$6,0)+57,0) -> 0.25 | H34: =+F34 -> 0.25 | I34: =+G34 -> 0.25 | K34: =+VLOOKUP(A34,'[1]B2B Red'!$C:$FG,MATCH($A$3,'[1]B2B Red'!$BG$6:$CU$6,0)+58,0) -> 0.29 | N34: =IF((F34-VLOOKUP($A34,[2]Peugeot!$A:$L,COLUMNS([2]Peugeot!$A$9:$F$9),0))*100=0,"ISO",(F34-VLOOKUP($A34,[2]Peugeot!$A:$L,COLUMNS([2]Peugeot!$A$9:$F$9),0))*100) -> ISO | O34: =IF((G34-VLOOKUP($A34,[2]Peugeot!$A:$L,COLUMNS([2]Peugeot!$A$9:$G$9),0))*100=0,"ISO",(G34-VLOOKUP($A34,[2]Peugeot!$A:$L,COLUMNS([2]Peugeot!$A$9:$G$9),0))*100) -> ISO | P34: =IF((K34-VLOOKUP($A34,[2]Peugeot!$A:$L,COLUMNS([2]Peugeot!$A$9:$K$9),0))*100=0,"ISO",(K34-VLOOKUP($A34,[2]Peugeot!$A:$L,COLUMNS([2]Peugeot!$A$9:$K$9),0))*100) -> ISO
E35: Stellantis | F35: =+F34-F36 -> 0.195 | G35: =+G34-G36 -> 0.195 | H35: =+H34-H36 -> 0.185 | I35: =+I34-I36 -> 0.185 | K35: =+K34-K36 -> 0.22 | N35: =+IF((ROUND(F35-HLOOKUP(F$7,[2]Peugeot!$F$7:$G$86,MATCH($A34,[2]Peugeot!$A$7:$A$86,0)+1,0),3))*100=0,"ISO",(F35-HLOOKUP(F$7,[2]Peugeot!$F$7:$G$86,MATCH($A34,[2]Peugeot!$A$7:$A$86,0)+1,0))*100) -> ISO | O35: =+IF((ROUND(G35-HLOOKUP(G$7,[2]Peugeot!$F$7:$G$86,MATCH($A34,[2]Peugeot!$A$7:$A$86,0)+1,0),3))*100=0,"ISO",(G35-HLOOKUP(G$7,[2]Peugeot!$F$7:$G$86,MATCH($A34,[2]Peugeot!$A$7:$A$86,0)+1,0))*100) -> ISO | P35: =IF((ROUND(K35-HLOOKUP(K$7,[2]Peugeot!$K$7:$L$86,MATCH($A34,[2]Peugeot!$A$7:$A$86,0)+1,0),3))*100=0,"ISO",(K35-HLOOKUP(K$7,[2]Peugeot!$K$7:$L$86,MATCH($A34,[2]Peugeot!$A$7:$A$86,0)+1,0))*100) -> ISO
E36: RED | F36: =+D34-VLOOKUP(A34,'[1]B2B Red'!$C:$FG,MATCH($A$3,'[1]B2B Red'!$CV$6:$EE$6,0)+97,0) -> 0.055 | G36: =+D34-VLOOKUP(A34,'[1]B2B Red'!$C:$FG,MATCH($A$3,'[1]B2B Red'!$CV$6:$EE$6,0)+98,0) -> 0.055 | H36: =+F36+1% -> 0.065 | I36: =+G36+1% -> 0.065 | K36: =+D34-VLOOKUP(A34,'[1]B2B Red'!$C:$FG,MATCH($A$3,'[1]B2B Red'!$CV$6:$EE$6,0)+99,0) -> 0.07 | N36: =+IF((ROUND(F36-HLOOKUP(F$7,[2]Peugeot!$F$7:$G$86,MATCH($A34,[2]Peugeot!$A$7:$A$86,0)+2,0),3))*100=0,"ISO",(F36-HLOOKUP(F$7,[2]Peugeot!$F$7:$G$86,MATCH($A34,[2]Peugeot!$A$7:$A$86,0)+2,0))*100) -> ISO | O36: =IF((ROUND(G36-HLOOKUP(G$7,[2]Peugeot!$F$7:$G$86,MATCH($A34,[2]Peugeot!$A$7:$A$86,0)+2,0),3))*100=0,"ISO",(G36-HLOOKUP(G$7,[2]Peugeot!$F$7:$G$86,MATCH($A34,[2]Peugeot!$A$7:$A$86,0)+2,0))*100) -> ISO | P36: =IF((ROUND(K36-HLOOKUP(K$7,[2]Peugeot!$K$7:$L$86,MATCH($A34,[2]Peugeot!$A$7:$A$86,0)+2,0),3))*100=0,"ISO",(K36-HLOOKUP(K$7,[2]Peugeot!$K$7:$L$86,MATCH($A34,[2]Peugeot!$A$7:$A$86,0)+2,0))*100) -> ISO
A38: RIFTER MCA ALLURE BLUEHDI 100 | C38: Familia RIFTER MCA | D38: =VLOOKUP(A38,[1]Gestión!$D:$H,5,FALSE) -> 0.09 | E38: Total | F38: =+VLOOKUP(A38,'[1]B2B Red'!$C:$FG,MATCH($A$3,'[1]B2B Red'!$BG$6:$CU$6,0)+56,0) -> 0.1 | G38: =+VLOOKUP(A38,'[1]B2B Red'!$C:$FG,MATCH($A$3,'[1]B2B Red'!$BG$6:$CU$6,0)+57,0) -> 0.1 | H38: =+F38 -> 0.1 | I38: =+G38 -> 0.1 | K38: =+VLOOKUP(A38,'[1]B2B Red'!$C:$FG,MATCH($A$3,'[1]B2B Red'!$BG$6:$CU$6,0)+58,0) -> 0.14 | N38: =IF((F38-VLOOKUP($A38,[2]Peugeot!$A:$L,COLUMNS([2]Peugeot!$A$9:$F$9),0))*100=0,"ISO",(F38-VLOOKUP($A38,[2]Peugeot!$A:$L,COLUMNS([2]Peugeot!$A$9:$F$9),0))*100) -> ISO | O38: =IF((G38-VLOOKUP($A38,[2]Peugeot!$A:$L,COLUMNS([2]Peugeot!$A$9:$G$9),0))*100=0,"ISO",(G38-VLOOKUP($A38,[2]Peugeot!$A:$L,COLUMNS([2]Peugeot!$A$9:$G$9),0))*100) -> ISO | P38: =IF((K38-VLOOKUP($A38,[2]Peugeot!$A:$L,COLUMNS([2]Peugeot!$A$9:$K$9),0))*100=0,"ISO",(K38-VLOOKUP($A38,[2]Peugeot!$A:$L,COLUMNS([2]Peugeot!$A$9:$K$9),0))*100) -> ISO
E39: Stellantis | F39: =+F38-F40 -> 0.055 | G39: =+G38-G40 -> 0.055 | H39: =+H38-H40 -> 0.045 | I39: =+I38-I40 -> 0.045 | K39: =+K38-K40 -> 0.08 | N39: =+IF((ROUND(F39-HLOOKUP(F$7,[2]Peugeot!$F$7:$G$86,MATCH($A38,[2]Peugeot!$A$7:$A$86,0)+1,0),3))*100=0,"ISO",(F39-HLOOKUP(F$7,[2]Peugeot!$F$7:$G$86,MATCH($A38,[2]Peugeot!$A$7:$A$86,0)+1,0))*100) -> ISO | O39: =+IF((ROUND(G39-HLOOKUP(G$7,[2]Peugeot!$F$7:$G$86,MATCH($A38,[2]Peugeot!$A$7:$A$86,0)+1,0),3))*100=0,"ISO",(G39-HLOOKUP(G$7,[2]Peugeot!$F$7:$G$86,MATCH($A38,[2]Peugeot!$A$7:$A$86,0)+1,0))*100) -> ISO | P39: =IF((ROUND(K39-HLOOKUP(K$7,[2]Peugeot!$K$7:$L$86,MATCH($A38,[2]Peugeot!$A$7:$A$86,0)+1,0),3))*100=0,"ISO",(K39-HLOOKUP(K$7,[2]Peugeot!$K$7:$L$86,MATCH($A38,[2]Peugeot!$A$7:$A$86,0)+1,0))*100) -> ISO
E40: RED | F40: =+D38-VLOOKUP(A38,'[1]B2B Red'!$C:$FG,MATCH($A$3,'[1]B2B Red'!$CV$6:$EE$6,0)+97,0) -> 0.045 | G40: =+D38-VLOOKUP(A38,'[1]B2B Red'!$C:$FG,MATCH($A$3,'[1]B2B Red'!$CV$6:$EE$6,0)+98,0) -> 0.045 | H40: =+F40+1% -> 0.055 | I40: =+G40+1% -> 0.055 | K40: =+D38-VLOOKUP(A38,'[1]B2B Red'!$C:$FG,MATCH($A$3,'[1]B2B Red'!$CV$6:$EE$6,0)+99,0) -> 0.06 | N40: =+IF((ROUND(F40-HLOOKUP(F$7,[2]Peugeot!$F$7:$G$86,MATCH($A38,[2]Peugeot!$A$7:$A$86,0)+2,0),3))*100=0,"ISO",(F40-HLOOKUP(F$7,[2]Peugeot!$F$7:$G$86,MATCH($A38,[2]Peugeot!$A$7:$A$86,0)+2,0))*100) -> ISO | O40: =IF((ROUND(G40-HLOOKUP(G$7,[2]Peugeot!$F$7:$G$86,MATCH($A38,[2]Peugeot!$A$7:$A$86,0)+2,0),3))*100=0,"ISO",(G40-HLOOKUP(G$7,[2]Peugeot!$F$7:$G$86,MATCH($A38,[2]Peugeot!$A$7:$A$86,0)+2,0))*100) -> ISO | P40: =IF((ROUND(K40-HLOOKUP(K$7,[2]Peugeot!$K$7:$L$86,MATCH($A38,[2]Peugeot!$A$7:$A$86,0)+2,0),3))*100=0,"ISO",(K40-HLOOKUP(K$7,[2]Peugeot!$K$7:$L$86,MATCH($A38,[2]Peugeot!$A$7:$A$86,0)+2,0))*100) -> ISO
C42: Otros VP
A44: 208 MCA Style Puretech 100 | C44: Familia 208 / 2008 | D44: =VLOOKUP(A44,[1]Gestión!$D:$H,5,FALSE) -> 0.09 | E44: Total | F44: =+VLOOKUP(A44,'[1]B2B Red'!$C:$FG,MATCH($A$3,'[1]B2B Red'!$BG$6:$CU$6,0)+56,0) -> 0.08 | G44: =+VLOOKUP(A44,'[1]B2B Red'!$C:$FG,MATCH($A$3,'[1]B2B Red'!$BG$6:$CU$6,0)+57,0) -> 0.1 | H44: =+F44 -> 0.08 | I44: =+G44 -> 0.1 | K44: =+VLOOKUP(A44,'[1]B2B Red'!$C:$FG,MATCH($A$3,'[1]B2B Red'!$BG$6:$CU$6,0)+58,0) -> 0.14 | N44: =IF((F44-VLOOKUP($A44,[2]Peugeot!$A:$L,COLUMNS([2]Peugeot!$A$9:$F$9),0))*100=0,"ISO",(F44-VLOOKUP($A44,[2]Peugeot!$A:$L,COLUMNS([2]Peugeot!$A$9:$F$9),0))*100) -> ISO | O44: =IF((G44-VLOOKUP($A44,[2]Peugeot!$A:$L,COLUMNS([2]Peugeot!$A$9:$G$9),0))*100=0,"ISO",(G44-VLOOKUP($A44,[2]Peugeot!$A:$L,COLUMNS([2]Peugeot!$A$9:$G$9),0))*100) -> ISO | P44: =IF((K44-VLOOKUP($A44,[2]Peugeot!$A:$L,COLUMNS([2]Peugeot!$A$9:$K$9),0))*100=0,"ISO",(K44-VLOOKUP($A44,[2]Peugeot!$A:$L,COLUMNS([2]Peugeot!$A$9:$K$9),0))*100) -> ISO
A45: 208 MCA ACTIVE PURETECH 75 | E45: Stellantis | F45: =+F44-F46 -> 0.045 | G45: =+G44-G46 -> 0.055 | H45: =+H44-H46 -> 0.035 | I45: =+I44-I46 -> 0.045 | K45: =+K44-K46 -> 0.08 | N45: =+IF((ROUND(F45-HLOOKUP(F$7,[2]Peugeot!$F$7:$G$86,MATCH($A44,[2]Peugeot!$A$7:$A$86,0)+1,0),3))*100=0,"ISO",(F45-HLOOKUP(F$7,[2]Peugeot!$F$7:$G$86,MATCH($A44,[2]Peugeot!$A$7:$A$86,0)+1,0))*100) -> ISO | O45: =+IF((ROUND(G45-HLOOKUP(G$7,[2]Peugeot!$F$7:$G$86,MATCH($A44,[2]Peugeot!$A$7:$A$86,0)+1,0),3))*100=0,"ISO",(G45-HLOOKUP(G$7,[2]Peugeot!$F$7:$G$86,MATCH($A44,[2]Peugeot!$A$7:$A$86,0)+1,0))*100) -> ISO | P45: =IF((ROUND(K45-HLOOKUP(K$7,[2]Peugeot!$K$7:$L$86,MATCH($A44,[2]Peugeot!$A$7:$A$86,0)+1,0),3))*100=0,"ISO",(K45-HLOOKUP(K$7,[2]Peugeot!$K$7:$L$86,MATCH($A44,[2]Peugeot!$A$7:$A$86,0)+1,0))*100) -> ISO
E46: RED | F46: =+D44-VLOOKUP(A44,'[1]B2B Red'!$C:$FG,MATCH($A$3,'[1]B2B Red'!$CV$6:$EE$6,0)+97,0) -> 0.035 | G46: =+D44-VLOOKUP(A44,'[1]B2B Red'!$C:$FG,MATCH($A$3,'[1]B2B Red'!$CV$6:$EE$6,0)+98,0) -> 0.045 | H46: =+F46+1% -> 0.045 | I46: =+G46+1% -> 0.055 | K46: =+D44-VLOOKUP(A44,'[1]B2B Red'!$C:$FG,MATCH($A$3,'[1]B2B Red'!$CV$6:$EE$6,0)+99,0) -> 0.06 | N46: =+IF((ROUND(F46-HLOOKUP(F$7,[2]Peugeot!$F$7:$G$86,MATCH($A44,[2]Peugeot!$A$7:$A$86,0)+2,0),3))*100=0,"ISO",(F46-HLOOKUP(F$7,[2]Peugeot!$F$7:$G$86,MATCH($A44,[2]Peugeot!$A$7:$A$86,0)+2,0))*100) -> ISO | O46: =IF((ROUND(G46-HLOOKUP(G$7,[2]Peugeot!$F$7:$G$86,MATCH($A44,[2]Peugeot!$A$7:$A$86,0)+2,0),3))*100=0,"ISO",(G46-HLOOKUP(G$7,[2]Peugeot!$F$7:$G$86,MATCH($A44,[2]Peugeot!$A$7:$A$86,0)+2,0))*100) -> ISO | P46: =IF((ROUND(K46-HLOOKUP(K$7,[2]Peugeot!$K$7:$L$86,MATCH($A44,[2]Peugeot!$A$7:$A$86,0)+2,0),3))*100=0,"ISO",(K46-HLOOKUP(K$7,[2]Peugeot!$K$7:$L$86,MATCH($A44,[2]Peugeot!$A$7:$A$86,0)+2,0))*100) -> ISO
A47: 308 Allure Puretech EAT8 | C47: Familia 308 | D47: =VLOOKUP(A47,[1]Gestión!$D:$H,5,FALSE) -> 0.09 | E47: Total | F47: =+VLOOKUP(A47,'[1]B2B Red'!$C:$FG,MATCH($A$3,'[1]B2B Red'!$BG$6:$CU$6,0)+56,0) -> 0.08 | G47: =+VLOOKUP(A47,'[1]B2B Red'!$C:$FG,MATCH($A$3,'[1]B2B Red'!$BG$6:$CU$6,0)+57,0) -> 0.1 | H47: =+F47 -> 0.08 | I47: =+G47 -> 0.1 | K47: =+VLOOKUP(A47,'[1]B2B Red'!$C:$FG,MATCH($A$3,'[1]B2B Red'!$BG$6:$CU$6,0)+58,0) -> 0.14 | N47: =IF((F47-VLOOKUP($A47,[2]Peugeot!$A:$L,COLUMNS([2]Peugeot!$A$9:$F$9),0))*100=0,"ISO",(F47-VLOOKUP($A47,[2]Peugeot!$A:$L,COLUMNS([2]Peugeot!$A$9:$F$9),0))*100) -> ISO | O47: =IF((G47-VLOOKUP($A47,[2]Peugeot!$A:$L,COLUMNS([2]Peugeot!$A$9:$G$9),0))*100=0,"ISO",(G47-VLOOKUP($A47,[2]Peugeot!$A:$L,COLUMNS([2]Peugeot!$A$9:$G$9),0))*100) -> ISO | P47: =IF((K47-VLOOKUP($A47,[2]Peugeot!$A:$L,COLUMNS([2]Peugeot!$A$9:$K$9),0))*100=0,"ISO",(K47-VLOOKUP($A47,[2]Peugeot!$A:$L,COLUMNS([2]Peugeot!$A$9:$K$9),0))*100) -> ISO
E48: Stellantis | F48: =+F47-F49 -> 0.045 | G48: =+G47-G49 -> 0.055 | H48: =+H47-H49 -> 0.035 | I48: =+I47-I49 -> 0.045 | K48: =+K47-K49 -> 0.08 | N48: =+IF((ROUND(F48-HLOOKUP(F$7,[2]Peugeot!$F$7:$G$86,MATCH($A47,[2]Peugeot!$A$7:$A$86,0)+1,0),3))*100=0,"ISO",(F48-HLOOKUP(F$7,[2]Peugeot!$F$7:$G$86,MATCH($A47,[2]Peugeot!$A$7:$A$86,0)+1,0))*100) -> ISO | O48: =+IF((ROUND(G48-HLOOKUP(G$7,[2]Peugeot!$F$7:$G$86,MATCH($A47,[2]Peugeot!$A$7:$A$86,0)+1,0),3))*100=0,"ISO",(G48-HLOOKUP(G$7,[2]Peugeot!$F$7:$G$86,MATCH($A47,[2]Peugeot!$A$7:$A$86,0)+1,0))*100) -> ISO | P48: =IF((ROUND(K48-HLOOKUP(K$7,[2]Peugeot!$K$7:$L$86,MATCH($A47,[2]Peugeot!$A$7:$A$86,0)+1,0),3))*100=0,"ISO",(K48-HLOOKUP(K$7,[2]Peugeot!$K$7:$L$86,MATCH($A47,[2]Peugeot!$A$7:$A$86,0)+1,0))*100) -> ISO
E49: RED | F49: =+D47-VLOOKUP(A47,'[1]B2B Red'!$C:$FG,MATCH($A$3,'[1]B2B Red'!$CV$6:$EE$6,0)+97,0) -> 0.035 | G49: =+D47-VLOOKUP(A47,'[1]B2B Red'!$C:$FG,MATCH($A$3,'[1]B2B Red'!$CV$6:$EE$6,0)+98,0) -> 0.045 | H49: =+F49+1% -> 0.045 | I49: =+G49+1% -> 0.055 | K49: =+D47-VLOOKUP(A47,'[1]B2B Red'!$C:$FG,MATCH($A$3,'[1]B2B Red'!$CV$6:$EE$6,0)+99,0) -> 0.06 | N49: =+IF((ROUND(F49-HLOOKUP(F$7,[2]Peugeot!$F$7:$G$86,MATCH($A47,[2]Peugeot!$A$7:$A$86,0)+2,0),3))*100=0,"ISO",(F49-HLOOKUP(F$7,[2]Peugeot!$F$7:$G$86,MATCH($A47,[2]Peugeot!$A$7:$A$86,0)+2,0))*100) -> ISO | O49: =IF((ROUND(G49-HLOOKUP(G$7,[2]Peugeot!$F$7:$G$86,MATCH($A47,[2]Peugeot!$A$7:$A$86,0)+2,0),3))*100=0,"ISO",(G49-HLOOKUP(G$7,[2]Peugeot!$F$7:$G$86,MATCH($A47,[2]Peugeot!$A$7:$A$86,0)+2,0))*100) -> ISO | P49: =IF((ROUND(K49-HLOOKUP(K$7,[2]Peugeot!$K$7:$L$86,MATCH($A47,[2]Peugeot!$A$7:$A$86,0)+2,0),3))*100=0,"ISO",(K49-HLOOKUP(K$7,[2]Peugeot!$K$7:$L$86,MATCH($A47,[2]Peugeot!$A$7:$A$86,0)+2,0))*100) -> ISO
A50: New 3008 Allure MHEV 136 eDCT6 | C50: Familia Nuevo 3008 | D50: =VLOOKUP(A50,[1]Gestión!$D:$H,5,FALSE) -> 0.09 | E50: Total | F50: =+VLOOKUP(A50,'[1]B2B Red'!$C:$FG,MATCH($A$3,'[1]B2B Red'!$BG$6:$CU$6,0)+56,0) -> 0.08 | G50: =+VLOOKUP(A50,'[1]B2B Red'!$C:$FG,MATCH($A$3,'[1]B2B Red'!$BG$6:$CU$6,0)+57,0) -> 0.1 | H50: =+F50 -> 0.08 | I50: =+G50 -> 0.1 | K50: =+VLOOKUP(A50,'[1]B2B Red'!$C:$FG,MATCH($A$3,'[1]B2B Red'!$BG$6:$CU$6,0)+58,0) -> 0.14 | N50: =IF((F50-VLOOKUP($A50,[2]Peugeot!$A:$L,COLUMNS([2]Peugeot!$A$9:$F$9),0))*100=0,"ISO",(F50-VLOOKUP($A50,[2]Peugeot!$A:$L,COLUMNS([2]Peugeot!$A$9:$F$9),0))*100) -> ISO | O50: =IF((G50-VLOOKUP($A50,[2]Peugeot!$A:$L,COLUMNS([2]Peugeot!$A$9:$G$9),0))*100=0,"ISO",(G50-VLOOKUP($A50,[2]Peugeot!$A:$L,COLUMNS([2]Peugeot!$A$9:$G$9),0))*100) -> ISO | P50: =IF((K50-VLOOKUP($A50,[2]Peugeot!$A:$L,COLUMNS([2]Peugeot!$A$9:$K$9),0))*100=0,"ISO",(K50-VLOOKUP($A50,[2]Peugeot!$A:$L,COLUMNS([2]Peugeot!$A$9:$K$9),0))*100) -> ISO
...

Sheet RAM
A2: MES
A3: =+Peugeot!A3 -> JUNIO | C3: =" "&"ACCIONES COMERCIALES B2B RED"&" - "&A3&" 2026" -> ACCIONES COMERCIALES B2B RED - JUNIO 2026
C6: TABLA DESCUENTOS FLOTAS | F6: Conces. Professional | H6: Conces. No Professional
F7: Tramo 1 (1 a 5) | G7: Tramo 2 (6 a 99) | H7: Tramo 1 (1 a 5) | I7: Tramo 2 (6 a 99) | K7: Grandes Cuentas (sobre 100) | N7: ∆ M-1 Tramo 1 (pp) | O7: ∆ M-1 Tramo 2 (pp) | P7: ∆ M-1 GC (pp)
C8: Versión | D8: Margen Fijo | E8: Aportes
A9: RAM 700 SLT SINGLE CAB 1.3 MT | C9: Familia RAM 700 | D9: =VLOOKUP(A9,[3]Gestión!$D:$H,5,FALSE) -> 0.08 | E9: Total | F9: =+VLOOKUP(A9,'[3]B2B Red'!$C:$FG,MATCH($A$3,'[3]B2B Red'!$BG$6:$CU$6,0)+56,0) -> 0.12 | G9: =+VLOOKUP(A9,'[3]B2B Red'!$C:$FG,MATCH($A$3,'[3]B2B Red'!$BG$6:$CU$6,0)+57,0) -> 0.14 | H9: =+F9 -> 0.12 | I9: =+G9 -> 0.14 | K9: =+VLOOKUP(A9,'[3]B2B Red'!$C:$FG,MATCH($A$3,'[3]B2B Red'!$BG$6:$CU$6,0)+58,0) -> 0.18 | N9: =IF((F9-VLOOKUP($C9,[2]RAM!$C:$L,COLUMNS([2]RAM!$C$9:$F$9),0))*100=0,"ISO",(F9-VLOOKUP($C9,[2]RAM!$C:$L,COLUMNS([2]RAM!$C$9:$F$9),0))*100) -> ISO | O9: =IF((G9-VLOOKUP($C9,[2]RAM!$C:$L,COLUMNS([2]RAM!$C$9:$G$9),0))*100=0,"ISO",(G9-VLOOKUP($C9,[2]RAM!$C:$L,COLUMNS([2]RAM!$C$9:$G$9),0))*100) -> ISO | P9: =IF((K9-VLOOKUP($C9,[2]RAM!$C:$L,COLUMNS([2]RAM!$C$9:$K$9),0))*100=0,"ISO",(K9-VLOOKUP($C9,[2]RAM!$C:$L,COLUMNS([2]RAM!$C$9:$K$9),0))*100) -> ISO
E10: Stellantis | F10: =+F9-F11 -> 0.095 | G10: =+G9-G11 -> 0.105 | H10: =+H9-H11 -> 0.085 | I10: =+I9-I11 -> 0.095 | K10: =+K9-K11 -> 0.13 | N10: =+IF((ROUND(F10-HLOOKUP(F$7,[2]RAM!$F$7:$G$86,MATCH($C9,[2]RAM!$C$7:$C$86,0)+1,0),3))*100=0,"ISO",(F10-HLOOKUP(F$7,[2]RAM!$F$7:$G$86,MATCH($C9,[2]RAM!$C$7:$C$86,0)+1,0))*100) -> ISO | O10: =+IF((ROUND(G10-HLOOKUP(G$7,[2]RAM!$F$7:$G$86,MATCH($C9,[2]RAM!$C$7:$C$86,0)+1,0),3))*100=0,"ISO",(G10-HLOOKUP(G$7,[2]RAM!$F$7:$G$86,MATCH($C9,[2]RAM!$C$7:$C$86,0)+1,0))*100) -> ISO | P10: =IF((ROUND(K10-HLOOKUP(K$7,[2]RAM!$K$7:$L$86,MATCH($C9,[2]RAM!$C$7:$C$86,0)+1,0),3))*100=0,"ISO",(K10-HLOOKUP(K$7,[2]RAM!$K$7:$L$86,MATCH($C9,[2]RAM!$C$7:$C$86,0)+1,0))*100) -> ISO
E11: RED | F11: =+D9-VLOOKUP(A9,'[3]B2B Red'!$C:$FG,MATCH($A$3,'[3]B2B Red'!$CV$6:$EE$6,0)+97,0) -> 0.025 | G11: =+D9-VLOOKUP(A9,'[3]B2B Red'!$C:$FG,MATCH($A$3,'[3]B2B Red'!$CV$6:$EE$6,0)+98,0) -> 0.035 | H11: =+F11+1% -> 0.035 | I11: =+G11+1% -> 0.045 | K11: =+D9-VLOOKUP(A9,'[3]B2B Red'!$C:$FG,MATCH($A$3,'[3]B2B Red'!$CV$6:$EE$6,0)+99,0) -> 0.05 | N11: =+IF((ROUND(F11-HLOOKUP(F$7,[2]RAM!$F$7:$G$86,MATCH($C9,[2]RAM!$C$7:$C$86,0)+2,0),3))*100=0,"ISO",(F11-HLOOKUP(F$7,[2]RAM!$F$7:$G$86,MATCH($C9,[2]RAM!$C$7:$C$86,0)+2,0))*100) -> ISO | O11: =IF((ROUND(G11-HLOOKUP(G$7,[2]RAM!$F$7:$G$86,MATCH($C9,[2]RAM!$C$7:$C$86,0)+2,0),3))*100=0,"ISO",(G11-HLOOKUP(G$7,[2]RAM!$F$7:$G$86,MATCH($C9,[2]RAM!$C$7:$C$86,0)+2,0))*100) -> ISO | P11: =IF((ROUND(K11-HLOOKUP(K$7,[2]RAM!$K$7:$L$86,MATCH($C9,[2]RAM!$C$7:$C$86,0)+2,0),3))*100=0,"ISO",(K11-HLOOKUP(K$7,[2]RAM!$K$7:$L$86,MATCH($C9,[2]RAM!$C$7:$C$86,0)+2,0))*100) -> ISO
A13: RAM RAMPAGE BIGHORN 2.2 DIESEL 200 HP 4X4 AT | C13: RAMPAGE BIGHORN | D13: =VLOOKUP(A13,[3]Gestión!$D:$H,5,FALSE) -> 0.1 | E13: Total | F13: =+VLOOKUP(A13,'[3]B2B Red'!$C:$FG,MATCH($A$3,'[3]B2B Red'!$BG$6:$CU$6,0)+56,0) -> 0.13 | G13: =+VLOOKUP(A13,'[3]B2B Red'!$C:$FG,MATCH($A$3,'[3]B2B Red'!$BG$6:$CU$6,0)+57,0) -> 0.15 | H13: =+F13 -> 0.13 | I13: =+G13 -> 0.15 | K13: =+VLOOKUP(A13,'[3]B2B Red'!$C:$FG,MATCH($A$3,'[3]B2B Red'!$BG$6:$CU$6,0)+58,0) -> 0.17 | N13: =IF((F13-VLOOKUP($A13,[2]RAM!$A:$L,COLUMNS([2]RAM!$A$9:$F$9),0))*100=0,"ISO",(F13-VLOOKUP($A13,[2]RAM!$A:$L,COLUMNS([2]RAM!$A$9:$F$9),0))*100) -> -3 | O13: =IF((G13-VLOOKUP($A13,[2]RAM!$A:$L,COLUMNS([2]RAM!$A$9:$G$9),0))*100=0,"ISO",(G13-VLOOKUP($A13,[2]RAM!$A:$L,COLUMNS([2]RAM!$A$9:$G$9),0))*100) -> -3 | P13: =IF((K13-VLOOKUP($A13,[2]RAM!$A:$L,COLUMNS([2]RAM!$A$9:$K$9),0))*100=0,"ISO",(K13-VLOOKUP($A13,[2]RAM!$A:$L,COLUMNS([2]RAM!$A$9:$K$9),0))*100) -> -3
E14: Stellantis | F14: =+F13-F15 -> 0.075 | G14: =+G13-G15 -> 0.095 | H14: =+H13-H15 -> 0.065 | I14: =+I13-I15 -> 0.085 | K14: =+K13-K15 -> 0.11 | N14: =+IF((ROUND(F14-HLOOKUP(F$7,[2]RAM!$F$7:$G$86,MATCH($A13,[2]RAM!$A$7:$A$86,0)+1,0),3))*100=0,"ISO",(F14-HLOOKUP(F$7,[2]RAM!$F$7:$G$86,MATCH($A13,[2]RAM!$A$7:$A$86,0)+1,0))*100) -> -3 | O14: =+IF((ROUND(G14-HLOOKUP(G$7,[2]RAM!$F$7:$G$86,MATCH($A13,[2]RAM!$A$7:$A$86,0)+1,0),3))*100=0,"ISO",(G14-HLOOKUP(G$7,[2]RAM!$F$7:$G$86,MATCH($A13,[2]RAM!$A$7:$A$86,0)+1,0))*100) -> -3 | P14: =IF((ROUND(K14-HLOOKUP(K$7,[2]RAM!$K$7:$L$86,MATCH($A13,[2]RAM!$A$7:$A$86,0)+1,0),3))*100=0,"ISO",(K14-HLOOKUP(K$7,[2]RAM!$K$7:$L$86,MATCH($A13,[2]RAM!$A$7:$A$86,0)+1,0))*100) -> -3
E15: RED | F15: =+D13-VLOOKUP(A13,'[3]B2B Red'!$C:$FG,MATCH($A$3,'[3]B2B Red'!$CV$6:$EE$6,0)+97,0) -> 0.055 | G15: =+D13-VLOOKUP(A13,'[3]B2B Red'!$C:$FG,MATCH($A$3,'[3]B2B Red'!$CV$6:$EE$6,0)+98,0) -> 0.055 | H15: =+F15+1% -> 0.065 | I15: =+G15+1% -> 0.065 | K15: =+D13-VLOOKUP(A13,'[3]B2B Red'!$C:$FG,MATCH($A$3,'[3]B2B Red'!$CV$6:$EE$6,0)+99,0) -> 0.06 | N15: =+IF((ROUND(F15-HLOOKUP(F$7,[2]RAM!$F$7:$G$86,MATCH($A13,[2]RAM!$A$7:$A$86,0)+2,0),3))*100=0,"ISO",(F15-HLOOKUP(F$7,[2]RAM!$F$7:$G$86,MATCH($A13,[2]RAM!$A$7:$A$86,0)+2,0))*100) -> ISO | O15: =+IF((ROUND(G15-HLOOKUP(G$7,[2]RAM!$F$7:$G$86,MATCH($A13,[2]RAM!$A$7:$A$86,0)+2,0),3))*100=0,"ISO",(G15-HLOOKUP(G$7,[2]RAM!$F$7:$G$86,MATCH($A13,[2]RAM!$A$7:$A$86,0)+2,0))*100) -> ISO | P15: =IF((ROUND(K15-HLOOKUP(K$7,[2]RAM!$K$7:$L$86,MATCH($A13,[2]RAM!$A$7:$A$86,0)+2,0),3))*100=0,"ISO",(K15-HLOOKUP(K$7,[2]RAM!$K$7:$L$86,MATCH($A13,[2]RAM!$A$7:$A$86,0)+2,0))*100) -> ISO
A17: RAM RAMPAGE LARAMIE 2.2 DIESEL 200 HP 4X4 AT | C17: RAMPAGE LARAMIE | D17: =VLOOKUP(A17,[3]Gestión!$D:$H,5,FALSE) -> 0.1 | E17: Total | F17: =+VLOOKUP(A17,'[3]B2B Red'!$C:$FG,MATCH($A$3,'[3]B2B Red'!$BG$6:$CU$6,0)+56,0) -> 0.15 | G17: =+VLOOKUP(A17,'[3]B2B Red'!$C:$FG,MATCH($A$3,'[3]B2B Red'!$BG$6:$CU$6,0)+57,0) -> 0.17 | H17: =+F17 -> 0.15 | I17: =+G17 -> 0.17 | K17: =+VLOOKUP(A17,'[3]B2B Red'!$C:$FG,MATCH($A$3,'[3]B2B Red'!$BG$6:$CU$6,0)+58,0) -> 0.19 | N17: =IF((F17-VLOOKUP($A13,[2]RAM!$A:$L,COLUMNS([2]RAM!$A$9:$F$9),0))*100=0,"ISO",(F17-VLOOKUP($A13,[2]RAM!$A:$L,COLUMNS([2]RAM!$A$9:$F$9),0))*100) -> -1 | O17: =IF((G17-VLOOKUP($A13,[2]RAM!$A:$L,COLUMNS([2]RAM!$A$9:$G$9),0))*100=0,"ISO",(G17-VLOOKUP($A13,[2]RAM!$A:$L,COLUMNS([2]RAM!$A$9:$G$9),0))*100) -> -1 | P17: =IF((K17-VLOOKUP($A13,[2]RAM!$A:$L,COLUMNS([2]RAM!$A$9:$K$9),0))*100=0,"ISO",(K17-VLOOKUP($A13,[2]RAM!$A:$L,COLUMNS([2]RAM!$A$9:$K$9),0))*100) -> -1
E18: Stellantis | F18: =+F17-F19 -> 0.095 | G18: =+G17-G19 -> 0.115 | H18: =+H17-H19 -> 0.085 | I18: =+I17-I19 -> 0.105 | K18: =+K17-K19 -> 0.13 | N18: =+IF((ROUND(F18-HLOOKUP(F$7,[2]RAM!$F$7:$G$86,MATCH($A13,[2]RAM!$A$7:$A$86,0)+1,0),3))*100=0,"ISO",(F18-HLOOKUP(F$7,[2]RAM!$F$7:$G$86,MATCH($A13,[2]RAM!$A$7:$A$86,0)+1,0))*100) -> -1 | O18: =+IF((ROUND(G18-HLOOKUP(G$7,[2]RAM!$F$7:$G$86,MATCH($A13,[2]RAM!$A$7:$A$86,0)+1,0),3))*100=0,"ISO",(G18-HLOOKUP(G$7,[2]RAM!$F$7:$G$86,MATCH($A13,[2]RAM!$A$7:$A$86,0)+1,0))*100) -> -1 | P18: =IF((ROUND(K18-HLOOKUP(K$7,[2]RAM!$K$7:$L$86,MATCH($A13,[2]RAM!$A$7:$A$86,0)+1,0),3))*100=0,"ISO",(K18-HLOOKUP(K$7,[2]RAM!$K$7:$L$86,MATCH($A13,[2]RAM!$A$7:$A$86,0)+1,0))*100) -> -1
E19: RED | F19: =+D17-VLOOKUP(A17,'[3]B2B Red'!$C:$FG,MATCH($A$3,'[3]B2B Red'!$CV$6:$EE$6,0)+97,0) -> 0.055 | G19: =+D17-VLOOKUP(A17,'[3]B2B Red'!$C:$FG,MATCH($A$3,'[3]B2B Red'!$CV$6:$EE$6,0)+98,0) -> 0.055 | H19: =+F19+1% -> 0.065 | I19: =+G19+1% -> 0.065 | K19: =+D17-VLOOKUP(A17,'[3]B2B Red'!$C:$FG,MATCH($A$3,'[3]B2B Red'!$CV$6:$EE$6,0)+99,0) -> 0.06 | N19: =+IF((ROUND(F19-HLOOKUP(F$7,[2]RAM!$F$7:$G$86,MATCH($A13,[2]RAM!$A$7:$A$86,0)+2,0),3))*100=0,"ISO",(F19-HLOOKUP(F$7,[2]RAM!$F$7:$G$86,MATCH($A13,[2]RAM!$A$7:$A$86,0)+2,0))*100) -> ISO | O19: =+IF((ROUND(G19-HLOOKUP(G$7,[2]RAM!$F$7:$G$86,MATCH($A13,[2]RAM!$A$7:$A$86,0)+2,0),3))*100=0,"ISO",(G19-HLOOKUP(G$7,[2]RAM!$F$7:$G$86,MATCH($A13,[2]RAM!$A$7:$A$86,0)+2,0))*100) -> ISO | P19: =IF((ROUND(K19-HLOOKUP(K$7,[2]RAM!$K$7:$L$86,MATCH($A13,[2]RAM!$A$7:$A$86,0)+2,0),3))*100=0,"ISO",(K19-HLOOKUP(K$7,[2]RAM!$K$7:$L$86,MATCH($A13,[2]RAM!$A$7:$A$86,0)+2,0))*100) -> ISO
A21: RAM RAMPAGE R/T 2.0 GASOLINA 272 HP 4X4 AT | C21: RAMPAGE R/T | D21: =VLOOKUP(A21,[3]Gestión!$D:$H,5,FALSE) -> 0.1 | E21: Total | F21: =+VLOOKUP(A21,'[3]B2B Red'!$C:$FG,MATCH($A$3,'[3]B2B Red'!$BG$6:$CU$6,0)+56,0) -> 0.16 | G21: =+VLOOKUP(A21,'[3]B2B Red'!$C:$FG,MATCH($A$3,'[3]B2B Red'!$BG$6:$CU$6,0)+57,0) -> 0.18 | H21: =+F21 -> 0.16 | I21: =+G21 -> 0.18 | K21: =+VLOOKUP(A21,'[3]B2B Red'!$C:$FG,MATCH($A$3,'[3]B2B Red'!$BG$6:$CU$6,0)+58,0) -> 0.2 | N21: =IF((F21-VLOOKUP($A13,[2]RAM!$A:$L,COLUMNS([2]RAM!$A$9:$F$9),0))*100=0,"ISO",(F21-VLOOKUP($A13,[2]RAM!$A:$L,COLUMNS([2]RAM!$A$9:$F$9),0))*100) -> ISO | O21: =IF((G21-VLOOKUP($A13,[2]RAM!$A:$L,COLUMNS([2]RAM!$A$9:$G$9),0))*100=0,"ISO",(G21-VLOOKUP($A13,[2]RAM!$A:$L,COLUMNS([2]RAM!$A$9:$G$9),0))*100) -> ISO | P21: =IF((K21-VLOOKUP($A13,[2]RAM!$A:$L,COLUMNS([2]RAM!$A$9:$K$9),0))*100=0,"ISO",(K21-VLOOKUP($A13,[2]RAM!$A:$L,COLUMNS([2]RAM!$A$9:$K$9),0))*100) -> ISO
E22: Stellantis | F22: =+F21-F23 -> 0.105 | G22: =+G21-G23 -> 0.125 | H22: =+H21-H23 -> 0.095 | I22: =+I21-I23 -> 0.115 | K22: =+K21-K23 -> 0.14 | N22: =+IF((ROUND(F22-HLOOKUP(F$7,[2]RAM!$F$7:$G$86,MATCH($A13,[2]RAM!$A$7:$A$86,0)+1,0),3))*100=0,"ISO",(F22-HLOOKUP(F$7,[2]RAM!$F$7:$G$86,MATCH($A13,[2]RAM!$A$7:$A$86,0)+1,0))*100) -> ISO | O22: =+IF((ROUND(G22-HLOOKUP(G$7,[2]RAM!$F$7:$G$86,MATCH($A13,[2]RAM!$A$7:$A$86,0)+1,0),3))*100=0,"ISO",(G22-HLOOKUP(G$7,[2]RAM!$F$7:$G$86,MATCH($A13,[2]RAM!$A$7:$A$86,0)+1,0))*100) -> ISO | P22: =IF((ROUND(K22-HLOOKUP(K$7,[2]RAM!$K$7:$L$86,MATCH($A13,[2]RAM!$A$7:$A$86,0)+1,0),3))*100=0,"ISO",(K22-HLOOKUP(K$7,[2]RAM!$K$7:$L$86,MATCH($A13,[2]RAM!$A$7:$A$86,0)+1,0))*100) -> ISO
E23: RED | F23: =+D21-VLOOKUP(A21,'[3]B2B Red'!$C:$FG,MATCH($A$3,'[3]B2B Red'!$CV$6:$EE$6,0)+97,0) -> 0.055 | G23: =+D21-VLOOKUP(A21,'[3]B2B Red'!$C:$FG,MATCH($A$3,'[3]B2B Red'!$CV$6:$EE$6,0)+98,0) -> 0.055 | H23: =+F23+1% -> 0.065 | I23: =+G23+1% -> 0.065 | K23: =+D21-VLOOKUP(A21,'[3]B2B Red'!$C:$FG,MATCH($A$3,'[3]B2B Red'!$CV$6:$EE$6,0)+99,0) -> 0.06 | N23: =+IF((ROUND(F23-HLOOKUP(F$7,[2]RAM!$F$7:$G$86,MATCH($A13,[2]RAM!$A$7:$A$86,0)+2,0),3))*100=0,"ISO",(F23-HLOOKUP(F$7,[2]RAM!$F$7:$G$86,MATCH($A13,[2]RAM!$A$7:$A$86,0)+2,0))*100) -> ISO | O23: =+IF((ROUND(G23-HLOOKUP(G$7,[2]RAM!$F$7:$G$86,MATCH($A13,[2]RAM!$A$7:$A$86,0)+2,0),3))*100=0,"ISO",(G23-HLOOKUP(G$7,[2]RAM!$F$7:$G$86,MATCH($A13,[2]RAM!$A$7:$A$86,0)+2,0))*100) -> ISO | P23: =IF((ROUND(K23-HLOOKUP(K$7,[2]RAM!$K$7:$L$86,MATCH($A13,[2]RAM!$A$7:$A$86,0)+2,0),3))*100=0,"ISO",(K23-HLOOKUP(K$7,[2]RAM!$K$7:$L$86,MATCH($A13,[2]RAM!$A$7:$A$86,0)+2,0))*100) -> ISO
A25: RAM DAKOTA WARLOCK | C25: Familia DAKOTA | D25: =VLOOKUP(A25,[3]Gestión!$D:$H,5,FALSE) -> 0.1 | E25: Total | F25: =+VLOOKUP(A25,'[3]B2B Red'!$C:$FG,MATCH($A$3,'[3]B2B Red'!$BG$6:$CU$6,0)+56,0) -> 0.12 | G25: =+VLOOKUP(A25,'[3]B2B Red'!$C:$FG,MATCH($A$3,'[3]B2B Red'!$BG$6:$CU$6,0)+57,0) -> 0.16 | H25: =+F25 -> 0.12 | I25: =+G25 -> 0.16 | K25: =+VLOOKUP(A25,'[3]B2B Red'!$C:$FG,MATCH($A$3,'[3]B2B Red'!$BG$6:$CU$6,0)+58,0) -> 0.18 | N25: =IFERROR(IF((F25-VLOOKUP($A25,[2]RAM!$A:$L,COLUMNS([2]RAM!$A$9:$F$9),0))*100=0,"ISO",(F25-VLOOKUP($A25,[2]RAM!$A:$L,COLUMNS([2]RAM!$A$9:$F$9),0))*100),"N/A") -> ISO | O25: =IFERROR(IF((G25-VLOOKUP($A25,[2]RAM!$A:$L,COLUMNS([2]RAM!$A$9:$G$9),0))*100=0,"ISO",(G25-VLOOKUP($A25,[2]RAM!$A:$L,COLUMNS([2]RAM!$A$9:$G$9),0))*100),"N/A") -> ISO | P25: =IFERROR(IF((K25-VLOOKUP($A25,[2]RAM!$A:$L,COLUMNS([2]RAM!$A$9:$K$9),0))*100=0,"ISO",(K25-VLOOKUP($A25,[2]RAM!$A:$L,COLUMNS([2]RAM!$A$9:$K$9),0))*100),"N/A") -> ISO
E26: Stellantis | F26: =+F25-F27 -> 0.07 | G26: =+G25-G27 -> 0.105 | H26: =+H25-H27 -> 0.06 | I26: =+I25-I27 -> 0.095 | K26: =+K25-K27 -> 0.12 | N26: =IFERROR(IF((ROUND(F26-HLOOKUP(F$7,[2]RAM!$F$7:$G$86,MATCH($A25,[2]RAM!$A$7:$A$86,0)+1,0),3))*100=0,"ISO",(F26-HLOOKUP(F$7,[2]RAM!$F$7:$G$86,MATCH($A25,[2]RAM!$A$7:$A$86,0)+1,0))*100),"N/A") -> ISO | O26: =IFERROR(IF((ROUND(G26-HLOOKUP(G$7,[2]RAM!$F$7:$G$86,MATCH($A25,[2]RAM!$A$7:$A$86,0)+1,0),3))*100=0,"ISO",(G26-HLOOKUP(G$7,[2]RAM!$F$7:$G$86,MATCH($A25,[2]RAM!$A$7:$A$86,0)+1,0))*100),"N/A") -> ISO | P26: =IFERROR(IF((ROUND(K26-HLOOKUP(K$7,[2]RAM!$K$7:$L$86,MATCH($A25,[2]RAM!$A$7:$A$86,0)+1,0),3))*100=0,"ISO",(K26-HLOOKUP(K$7,[2]RAM!$K$7:$L$86,MATCH($A25,[2]RAM!$A$7:$A$86,0)+1,0))*100),"N/A") -> ISO
E27: RED | F27: =+D25-VLOOKUP(A25,'[3]B2B Red'!$C:$FG,MATCH($A$3,'[3]B2B Red'!$CV$6:$EE$6,0)+97,0) -> 0.05 | G27: =+D25-VLOOKUP(A25,'[3]B2B Red'!$C:$FG,MATCH($A$3,'[3]B2B Red'!$CV$6:$EE$6,0)+98,0) -> 0.055 | H27: =+F27+1% -> 0.06 | I27: =+G27+1% -> 0.065 | K27: =+D25-VLOOKUP(A25,'[3]B2B Red'!$C:$FG,MATCH($A$3,'[3]B2B Red'!$CV$6:$EE$6,0)+99,0) -> 0.06 | N27: =IFERROR(IF((ROUND(F27-HLOOKUP(F$7,[2]RAM!$F$7:$G$86,MATCH($A26,[2]RAM!$A$7:$A$86,0)+1,0),3))*100=0,"ISO",(F27-HLOOKUP(F$7,[2]RAM!$F$7:$G$86,MATCH($A26,[2]RAM!$A$7:$A$86,0)+1,0))*100),"N/A") -> N/A | O27: =IFERROR(IF((ROUND(G27-HLOOKUP(G$7,[2]RAM!$F$7:$G$86,MATCH($A26,[2]RAM!$A$7:$A$86,0)+1,0),3))*100=0,"ISO",(G27-HLOOKUP(G$7,[2]RAM!$F$7:$G$86,MATCH($A26,[2]RAM!$A$7:$A$86,0)+1,0))*100),"N/A") -> N/A | P27: =IFERROR(IF((ROUND(K27-HLOOKUP(K$7,[2]RAM!$K$7:$L$86,MATCH($A26,[2]RAM!$A$7:$A$86,0)+1,0),3))*100=0,"ISO",(K27-HLOOKUP(K$7,[2]RAM!$K$7:$L$86,MATCH($A26,[2]RAM!$A$7:$A$86,0)+1,0))*100),"N/A") -> N/A
A29: RAM 1500 BIGHORN NIGHT EDITION 3.6 V6 MILD HYBRID 305 HP 4X4 AT | C29: 1500 BIGHORN NIGHT EDITION | D29: 0.12 | E29: Total | F29: =+VLOOKUP(A29,'[3]B2B Red'!$C:$FG,MATCH($A$3,'[3]B2B Red'!$BG$6:$CU$6,0)+56,0) -> 0.16 | G29: =+VLOOKUP(A29,'[3]B2B Red'!$C:$FG,MATCH($A$3,'[3]B2B Red'!$BG$6:$CU$6,0)+57,0) -> 0.18 | H29: =+F29 -> 0.16 | I29: =+G29 -> 0.18 | K29: =+VLOOKUP(A29,'[3]B2B Red'!$C:$FG,MATCH($A$3,'[3]B2B Red'!$BG$6:$CU$6,0)+58,0) -> 0.2 | N29: =IF((F29-VLOOKUP($A29,[2]RAM!$A:$L,COLUMNS([2]RAM!$A$9:$F$9),0))*100=0,"ISO",(F29-VLOOKUP($A29,[2]RAM!$A:$L,COLUMNS([2]RAM!$A$9:$F$9),0))*100) -> ISO | O29: =IF((G29-VLOOKUP($A29,[2]RAM!$A:$L,COLUMNS([2]RAM!$A$9:$G$9),0))*100=0,"ISO",(G29-VLOOKUP($A29,[2]RAM!$A:$L,COLUMNS([2]RAM!$A$9:$G$9),0))*100) -> ISO | P29: =IF((K29-VLOOKUP($A29,[2]RAM!$A:$L,COLUMNS([2]RAM!$A$9:$K$9),0))*100=0,"ISO",(K29-VLOOKUP($A29,[2]RAM!$A:$L,COLUMNS([2]RAM!$A$9:$K$9),0))*100) -> ISO
E30: Stellantis | F30: =+F29-F31 -> 0.11 | G30: =+G29-G31 -> 0.11 | H30: =+H29-H31 -> 0.1 | I30: =+I29-I31 -> 0.1 | K30: =+K29-K31 -> 0.12 | N30: =+IF((ROUND(F30-HLOOKUP(F$7,[2]RAM!$F$7:$G$86,MATCH($A29,[2]RAM!$A$7:$A$86,0)+1,0),3))*100=0,"ISO",(F30-HLOOKUP(F$7,[2]RAM!$F$7:$G$86,MATCH($A29,[2]RAM!$A$7:$A$86,0)+1,0))*100) -> ISO | O30: =+IF((ROUND(G30-HLOOKUP(G$7,[2]RAM!$F$7:$G$86,MATCH($A29,[2]RAM!$A$7:$A$86,0)+1,0),3))*100=0,"ISO",(G30-HLOOKUP(G$7,[2]RAM!$F$7:$G$86,MATCH($A29,[2]RAM!$A$7:$A$86,0)+1,0))*100) -> ISO | P30: =IF((ROUND(K30-HLOOKUP(K$7,[2]RAM!$K$7:$L$86,MATCH($A29,[2]RAM!$A$7:$A$86,0)+1,0),3))*100=0,"ISO",(K30-HLOOKUP(K$7,[2]RAM!$K$7:$L$86,MATCH($A29,[2]RAM!$A$7:$A$86,0)+1,0))*100) -> ISO
E31: RED | F31: =+D29-VLOOKUP(A29,'[3]B2B Red'!$C:$FG,MATCH($A$3,'[3]B2B Red'!$CV$6:$EE$6,0)+97,0) -> 0.05 | G31: =+D29-VLOOKUP(A29,'[3]B2B Red'!$C:$FG,MATCH($A$3,'[3]B2B Red'!$CV$6:$EE$6,0)+98,0) -> 0.07 | H31: =+F31+1% -> 0.06 | I31: =+G31+1% -> 0.08 | K31: =+D29-VLOOKUP(A29,'[3]B2B Red'!$C:$FG,MATCH($A$3,'[3]B2B Red'!$CV$6:$EE$6,0)+99,0) -> 0.08 | N31: =+IF((ROUND(F31-HLOOKUP(F$7,[2]RAM!$F$7:$G$86,MATCH($A29,[2]RAM!$A$7:$A$86,0)+2,0),3))*100=0,"ISO",(F31-HLOOKUP(F$7,[2]RAM!$F$7:$G$86,MATCH($A29,[2]RAM!$A$7:$A$86,0)+2,0))*100) -> ISO | O31: =+IF((ROUND(G31-HLOOKUP(G$7,[2]RAM!$F$7:$G$86,MATCH($A29,[2]RAM!$A$7:$A$86,0)+2,0),3))*100=0,"ISO",(G31-HLOOKUP(G$7,[2]RAM!$F$7:$G$86,MATCH($A29,[2]RAM!$A$7:$A$86,0)+2,0))*100) -> ISO | P31: =IF((ROUND(K31-HLOOKUP(K$7,[2]RAM!$K$7:$L$86,MATCH($A29,[2]RAM!$A$7:$A$86,0)+2,0),3))*100=0,"ISO",(K31-HLOOKUP(K$7,[2]RAM!$K$7:$L$86,MATCH($A29,[2]RAM!$A$7:$A$86,0)+2,0))*100) -> ISO
A33: RAM 1500 BIGHORN 3.0 SO 420 HP 4X4 AT | C33: 1500 BIGHORN | D33: 0.12 | E33: Total | F33: =+VLOOKUP(A33,'[3]B2B Red'!$C:$FG,MATCH($A$3,'[3]B2B Red'!$BG$6:$CU$6,0)+56,0) -> 0.19 | G33: =+VLOOKUP(A33,'[3]B2B Red'!$C:$FG,MATCH($A$3,'[3]B2B Red'!$BG$6:$CU$6,0)+57,0) -> 0.21 | H33: =+F33 -> 0.19 | I33: =+G33 -> 0.21 | K33: =+VLOOKUP(A33,'[3]B2B Red'!$C:$FG,MATCH($A$3,'[3]B2B Red'!$BG$6:$CU$6,0)+58,0) -> 0.23 | N33: =IF((F33-VLOOKUP($A29,[2]RAM!$A:$L,COLUMNS([2]RAM!$A$9:$F$9),0))*100=0,"ISO",(F33-VLOOKUP($A29,[2]RAM!$A:$L,COLUMNS([2]RAM!$A$9:$F$9),0))*100) -> 3 | O33: =IF((G33-VLOOKUP($A29,[2]RAM!$A:$L,COLUMNS([2]RAM!$A$9:$G$9),0))*100=0,"ISO",(G33-VLOOKUP($A29,[2]RAM!$A:$L,COLUMNS([2]RAM!$A$9:$G$9),0))*100) -> 3 | P33: =IF((K33-VLOOKUP($A29,[2]RAM!$A:$L,COLUMNS([2]RAM!$A$9:$K$9),0))*100=0,"ISO",(K33-VLOOKUP($A29,[2]RAM!$A:$L,COLUMNS([2]RAM!$A$9:$K$9),0))*100) -> 3
E34: Stellantis | F34: =+F33-F35 -> 0.14 | G34: =+G33-G35 -> 0.14 | H34: =+H33-H35 -> 0.13 | I34: =+I33-I35 -> 0.13 | K34: =+K33-K35 -> 0.15 | N34: =+IF((ROUND(F34-HLOOKUP(F$7,[2]RAM!$F$7:$G$86,MATCH($A29,[2]RAM!$A$7:$A$86,0)+1,0),3))*100=0,"ISO",(F34-HLOOKUP(F$7,[2]RAM!$F$7:$G$86,MATCH($A29,[2]RAM!$A$7:$A$86,0)+1,0))*100) -> 3 | O34: =+IF((ROUND(G34-HLOOKUP(G$7,[2]RAM!$F$7:$G$86,MATCH($A29,[2]RAM!$A$7:$A$86,0)+1,0),3))*100=0,"ISO",(G34-HLOOKUP(G$7,[2]RAM!$F$7:$G$86,MATCH($A29,[2]RAM!$A$7:$A$86,0)+1,0))*100) -> 3 | P34: =IF((ROUND(K34-HLOOKUP(K$7,[2]RAM!$K$7:$L$86,MATCH($A29,[2]RAM!$A$7:$A$86,0)+1,0),3))*100=0,"ISO",(K34-HLOOKUP(K$7,[2]RAM!$K$7:$L$86,MATCH($A29,[2]RAM!$A$7:$A$86,0)+1,0))*100) -> 3
E35: RED | F35: =+D33-VLOOKUP(A33,'[3]B2B Red'!$C:$FG,MATCH($A$3,'[3]B2B Red'!$CV$6:$EE$6,0)+97,0) -> 0.05 | G35: =+D33-VLOOKUP(A33,'[3]B2B Red'!$C:$FG,MATCH($A$3,'[3]B2B Red'!$CV$6:$EE$6,0)+98,0) -> 0.07 | H35: =+F35+1% -> 0.06 | I35: =+G35+1% -> 0.08 | K35: =+D33-VLOOKUP(A33,'[3]B2B Red'!$C:$FG,MATCH($A$3,'[3]B2B Red'!$CV$6:$EE$6,0)+99,0) -> 0.08 | N35: =+IF((ROUND(F35-HLOOKUP(F$7,[2]RAM!$F$7:$G$86,MATCH($A29,[2]RAM!$A$7:$A$86,0)+2,0),3))*100=0,"ISO",(F35-HLOOKUP(F$7,[2]RAM!$F$7:$G$86,MATCH($A29,[2]RAM!$A$7:$A$86,0)+2,0))*100) -> ISO | O35: =+IF((ROUND(G35-HLOOKUP(G$7,[2]RAM!$F$7:$G$86,MATCH($A29,[2]RAM!$A$7:$A$86,0)+2,0),3))*100=0,"ISO",(G35-HLOOKUP(G$7,[2]RAM!$F$7:$G$86,MATCH($A29,[2]RAM!$A$7:$A$86,0)+2,0))*100) -> ISO | P35: =IF((ROUND(K35-HLOOKUP(K$7,[2]RAM!$K$7:$L$86,MATCH($A29,[2]RAM!$A$7:$A$86,0)+2,0),3))*100=0,"ISO",(K35-HLOOKUP(K$7,[2]RAM!$K$7:$L$86,MATCH($A29,[2]RAM!$A$7:$A$86,0)+2,0))*100) -> ISO
A37: RAM 1500 REBEL 3.0 SO 420 HP 4X4 AT | C37: 1500 REBEL / LARAMIE | D37: 0.12 | E37: Total | F37: =+VLOOKUP(A37,'[3]B2B Red'!$C:$FG,MATCH($A$3,'[3]B2B Red'!$BG$6:$CU$6,0)+56,0) -> 0.16 | G37: =+VLOOKUP(A37,'[3]B2B Red'!$C:$FG,MATCH($A$3,'[3]B2B Red'!$BG$6:$CU$6,0)+57,0) -> 0.18 | H37: =+F37 -> 0.16 | I37: =+G37 -> 0.18 | K37: =+VLOOKUP(A37,'[3]B2B Red'!$C:$FG,MATCH($A$3,'[3]B2B Red'!$BG$6:$CU$6,0)+58,0) -> 0.2 | N37: =IF((F37-VLOOKUP($A29,[2]RAM!$A:$L,COLUMNS([2]RAM!$A$9:$F$9),0))*100=0,"ISO",(F37-VLOOKUP($A29,[2]RAM!$A:$L,COLUMNS([2]RAM!$A$9:$F$9),0))*100) -> ISO | O37: =IF((G37-VLOOKUP($A29,[2]RAM!$A:$L,COLUMNS([2]RAM!$A$9:$G$9),0))*100=0,"ISO",(G37-VLOOKUP($A29,[2]RAM!$A:$L,COLUMNS([2]RAM!$A$9:$G$9),0))*100) -> ISO | P37: =IF((K37-VLOOKUP($A29,[2]RAM!$A:$L,COLUMNS([2]RAM!$A$9:$K$9),0))*100=0,"ISO",(K37-VLOOKUP($A29,[2]RAM!$A:$L,COLUMNS([2]RAM!$A$9:$K$9),0))*100) -> ISO
E38: Stellantis | F38: =+F37-F39 -> 0.11 | G38: =+G37-G39 -> 0.11 | H38: =+H37-H39 -> 0.1 | I38: =+I37-I39 -> 0.1 | K38: =+K37-K39 -> 0.12 | N38: =+IF((ROUND(F38-HLOOKUP(F$7,[2]RAM!$F$7:$G$86,MATCH($A29,[2]RAM!$A$7:$A$86,0)+1,0),3))*100=0,"ISO",(F38-HLOOKUP(F$7,[2]RAM!$F$7:$G$86,MATCH($A29,[2]RAM!$A$7:$A$86,0)+1,0))*100) -> ISO | O38: =+IF((ROUND(G38-HLOOKUP(G$7,[2]RAM!$F$7:$G$86,MATCH($A29,[2]RAM!$A$7:$A$86,0)+1,0),3))*100=0,"ISO",(G38-HLOOKUP(G$7,[2]RAM!$F$7:$G$86,MATCH($A29,[2]RAM!$A$7:$A$86,0)+1,0))*100) -> ISO | P38: =IF((ROUND(K38-HLOOKUP(K$7,[2]RAM!$K$7:$L$86,MATCH($A29,[2]RAM!$A$7:$A$86,0)+1,0),3))*100=0,"ISO",(K38-HLOOKUP(K$7,[2]RAM!$K$7:$L$86,MATCH($A29,[2]RAM!$A$7:$A$86,0)+1,0))*100) -> ISO
E39: RED | F39: =+D37-VLOOKUP(A37,'[3]B2B Red'!$C:$FG,MATCH($A$3,'[3]B2B Red'!$CV$6:$EE$6,0)+97,0) -> 0.05 | G39: =+D37-VLOOKUP(A37,'[3]B2B Red'!$C:$FG,MATCH($A$3,'[3]B2B Red'!$CV$6:$EE$6,0)+98,0) -> 0.07 | H39: =+F39+1% -> 0.06 | I39: =+G39+1% -> 0.08 | K39: =+D37-VLOOKUP(A37,'[3]B2B Red'!$C:$FG,MATCH($A$3,'[3]B2B Red'!$CV$6:$EE$6,0)+99,0) -> 0.08 | N39: =+IF((ROUND(F39-HLOOKUP(F$7,[2]RAM!$F$7:$G$86,MATCH($A29,[2]RAM!$A$7:$A$86,0)+2,0),3))*100=0,"ISO",(F39-HLOOKUP(F$7,[2]RAM!$F$7:$G$86,MATCH($A29,[2]RAM!$A$7:$A$86,0)+2,0))*100) -> ISO | O39: =+IF((ROUND(G39-HLOOKUP(G$7,[2]RAM!$F$7:$G$86,MATCH($A29,[2]RAM!$A$7:$A$86,0)+2,0),3))*100=0,"ISO",(G39-HLOOKUP(G$7,[2]RAM!$F$7:$G$86,MATCH($A29,[2]RAM!$A$7:$A$86,0)+2,0))*100) -> ISO | P39: =IF((ROUND(K39-HLOOKUP(K$7,[2]RAM!$K$7:$L$86,MATCH($A29,[2]RAM!$A$7:$A$86,0)+2,0),3))*100=0,"ISO",(K39-HLOOKUP(K$7,[2]RAM!$K$7:$L$86,MATCH($A29,[2]RAM!$A$7:$A$86,0)+2,0))*100) -> ISO
A41: RAM 1500 RHO 3.0 HO 540 HP 4x4 AT | C41: RAM 1500 RHO | D41: 0.12 | E41: Total | F41: =+VLOOKUP(A41,'[3]B2B Red'!$C:$FG,MATCH($A$3,'[3]B2B Red'!$BG$6:$CU$6,0)+56,0) -> 0.11 | G41: =+VLOOKUP(A41,'[3]B2B Red'!$C:$FG,MATCH($A$3,'[3]B2B Red'!$BG$6:$CU$6,0)+57,0) -> 0.14 | H41: =+F41 -> 0.11 | I41: =+G41 -> 0.14 | K41: =+VLOOKUP(A41,'[3]B2B Red'!$C:$FG,MATCH($A$3,'[3]B2B Red'!$BG$6:$CU$6,0)+58,0) -> 0.16 | N41: N/A | O41: N/A | P41: N/A
E42: Stellantis | F42: =+F41-F43 -> 0.06 | G42: =+G41-G43 -> 0.07 | H42: =+H41-H43 -> 0.05 | I42: =+I41-I43 -> 0.06 | K42: =+K41-K43 -> 0.08 | N42: N/A | O42: N/A | P42: N/A
E43: RED | F43: =+D41-VLOOKUP(A41,'[3]B2B Red'!$C:$FG,MATCH($A$3,'[3]B2B Red'!$CV$6:$EE$6,0)+97,0) -> 0.05 | G43: =+D41-VLOOKUP(A41,'[3]B2B Red'!$C:$FG,MATCH($A$3,'[3]B2B Red'!$CV$6:$EE$6,0)+98,0) -> 0.07 | H43: =+F43+1% -> 0.06 | I43: =+G43+1% -> 0.08 | K43: =+D41-VLOOKUP(A41,'[3]B2B Red'!$C:$FG,MATCH($A$3,'[3]B2B Red'!$CV$6:$EE$6,0)+99,0) -> 0.08 | N43: N/A | O43: N/A | P43: N/A
A45: RAM 2500 BIGHORN | C45: Familia RAM 2500 | D45: 0.12 | E45: Total | F45: =+VLOOKUP(A45,'[3]B2B Red'!$C:$FG,MATCH($A$3,'[3]B2B Red'!$BG$6:$CU$6,0)+56,0) -> 0.11 | G45: =+VLOOKUP(A45,'[3]B2B Red'!$C:$FG,MATCH($A$3,'[3]B2B Red'!$BG$6:$CU$6,0)+57,0) -> 0.14 | H45: =+F45 -> 0.11 | I45: =+G45 -> 0.14 | K45: =+VLOOKUP(A45,'[3]B2B Red'!$C:$FG,MATCH($A$3,'[3]B2B Red'!$BG$6:$CU$6,0)+58,0) -> 0.16 | N45: N/A | O45: N/A | P45: N/A
E46: Stellantis | F46: =+F45-F47 -> 0.055 | G46: =+G45-G47 -> 0.07 | H46: =+H45-H47 -> 0.045 | I46: =+I45-I47 -> 0.06 | K46: =+K45-K47 -> 0.08 | N46: N/A | O46: N/A | P46: N/A
E47: RED | F47: =+D45-VLOOKUP(A45,'[3]B2B Red'!$C:$FG,MATCH($A$3,'[3]B2B Red'!$CV$6:$EE$6,0)+97,0) -> 0.055 | G47: =+D45-VLOOKUP(A45,'[3]B2B Red'!$C:$FG,MATCH($A$3,'[3]B2B Red'!$CV$6:$EE$6,0)+98,0) -> 0.07 | H47: =+F47+1% -> 0.065 | I47: =+G47+1% -> 0.08 | K47: =+D45-VLOOKUP(A45,'[3]B2B Red'!$C:$FG,MATCH($A$3,'[3]B2B Red'!$CV$6:$EE$6,0)+99,0) -> 0.08 | N47: N/A | O47: N/A | P47: N/A

Sheet Citroën
A2: MES
A3: =+Peugeot!A3 -> JUNIO | C3: =" "&"ACCIONES COMERCIALES B2B RED"&" - "&A3&" 2026" -> ACCIONES COMERCIALES B2B RED - JUNIO 2026
C6: TABLA DESCUENTOS FLOTAS | F6: Conces. Professional | H6: Conces. No Professional
F7: Tramo 1 (1 a 5) | G7: Tramo 2 (6 a 99) | H7: Tramo 1 (1 a 5) | I7: Tramo 2 (6 a 99) | K7: Grandes Cuentas (sobre 100) | N7: ∆ M-1 Tramo 1 (pp) | O7: ∆ M-1 Tramo 2 (pp) | P7: ∆ M-1 GC (pp)
C8: Versión | D8: Margen Fijo | E8: Aportes
A9: Berlingo MCA M BlueHDi 100 | C9: Berlingo MCA M Diesel 100HP MT | D9: =VLOOKUP(A9,[4]Gestión!$D:$H,5,FALSE) -> 0.1 | E9: Total | F9: =+VLOOKUP(A9,'[4]B2B Red'!$C:$FG,MATCH($A$3,'[4]B2B Red'!$BG$6:$CU$6,0)+56,0) -> 0.14 | G9: =+VLOOKUP(A9,'[4]B2B Red'!$C:$FG,MATCH($A$3,'[4]B2B Red'!$BG$6:$CU$6,0)+57,0) -> 0.18 | H9: =+F9 -> 0.14 | I9: =+G9 -> 0.18 | K9: =+VLOOKUP(A9,'[4]B2B Red'!$C:$FG,MATCH($A$3,'[4]B2B Red'!$BG$6:$CU$6,0)+58,0)+4% -> 0.26 | N9: =IF((F9-VLOOKUP($A9,[2]Citroën!$A:$L,COLUMNS([2]Citroën!$A$9:$F$9),0))*100=0,"ISO",(F9-VLOOKUP($A9,[2]Citroën!$A:$L,COLUMNS([2]Citroën!$A$9:$F$9),0))*100) -> 2 | O9: =IF((G9-VLOOKUP($A9,[2]Citroën!$A:$L,COLUMNS([2]Citroën!$A$9:$G$9),0))*100=0,"ISO",(G9-VLOOKUP($A9,[2]Citroën!$A:$L,COLUMNS([2]Citroën!$A$9:$G$9),0))*100) -> 2 | P9: =IF((K9-VLOOKUP($A9,[2]Citroën!$A:$L,COLUMNS([2]Citroën!$A$9:$K$9),0))*100=0,"ISO",(K9-VLOOKUP($A9,[2]Citroën!$A:$L,COLUMNS([2]Citroën!$A$9:$K$9),0))*100) -> 2
A10: K9 VU | E10: Stellantis | F10: =+F9-F11 -> 0.095 | G10: =+G9-G11 -> 0.13 | H10: =+H9-H11 -> 0.085 | I10: =+I9-I11 -> 0.12 | K10: =+K9-K11 -> 0.18 | N10: =+IF((ROUND(F10-HLOOKUP(F$7,[2]Citroën!$F$7:$G$86,MATCH($A9,[2]Citroën!$A$7:$A$86,0)+1,0),3))*100=0,"ISO",(F10-HLOOKUP(F$7,[2]Citroën!$F$7:$G$86,MATCH($A9,[2]Citroën!$A$7:$A$86,0)+1,0))*100) -> 2 | O10: =+IF((ROUND(G10-HLOOKUP(G$7,[2]Citroën!$F$7:$G$86,MATCH($A9,[2]Citroën!$A$7:$A$86,0)+1,0),3))*100=0,"ISO",(G10-HLOOKUP(G$7,[2]Citroën!$F$7:$G$86,MATCH($A9,[2]Citroën!$A$7:$A$86,0)+1,0))*100) -> 2 | P10: =IF((ROUND(K10-HLOOKUP(K$7,[2]Citroën!$K$7:$L$86,MATCH($A9,[2]Citroën!$A$7:$A$86,0)+1,0),3))*100=0,"ISO",(K10-HLOOKUP(K$7,[2]Citroën!$K$7:$L$86,MATCH($A9,[2]Citroën!$A$7:$A$86,0)+1,0))*100) -> 1
E11: RED | F11: =+D9-VLOOKUP(A9,'[4]B2B Red'!$C:$FG,MATCH($A$3,'[4]B2B Red'!$CV$6:$EE$6,0)+97,0) -> 0.045 | G11: =+D9-VLOOKUP(A9,'[4]B2B Red'!$C:$FG,MATCH($A$3,'[4]B2B Red'!$CV$6:$EE$6,0)+98,0) -> 0.05 | H11: =+F11+1% -> 0.055 | I11: =+G11+1% -> 0.06 | K11: =+D9-VLOOKUP(A9,'[4]B2B Red'!$C:$FG,MATCH($A$3,'[4]B2B Red'!$CV$6:$EE$6,0)+99,0)+1% -> 0.08 | N11: =+IF((ROUND(F11-HLOOKUP(F$7,[2]Citroën!$F$7:$G$86,MATCH($A9,[2]Citroën!$A$7:$A$86,0)+2,0),3))*100=0,"ISO",(F11-HLOOKUP(F$7,[2]Citroën!$F$7:$G$86,MATCH($A9,[2]Citroën!$A$7:$A$86,0)+2,0))*100) -> ISO | O11: =IF((ROUND(G11-HLOOKUP(G$7,[2]Citroën!$F$7:$G$86,MATCH($A9,[2]Citroën!$A$7:$A$86,0)+2,0),3))*100=0,"ISO",(G11-HLOOKUP(G$7,[2]Citroën!$F$7:$G$86,MATCH($A9,[2]Citroën!$A$7:$A$86,0)+2,0))*100) -> ISO | P11: =IF((ROUND(K11-HLOOKUP(K$7,[2]Citroën!$K$7:$L$86,MATCH($A9,[2]Citroën!$A$7:$A$86,0)+2,0),3))*100=0,"ISO",(K11-HLOOKUP(K$7,[2]Citroën!$K$7:$L$86,MATCH($A9,[2]Citroën!$A$7:$A$86,0)+2,0))*100) -> 1
A13: Berlingo MCA XL BlueHDi 100 | C13: Berlingo MCA XL Diesel 100HP MT | D13: =VLOOKUP(A13,[4]Gestión!$D:$H,5,FALSE) -> 0.1 | E13: Total | F13: =+VLOOKUP(A13,'[4]B2B Red'!$C:$FG,MATCH($A$3,'[4]B2B Red'!$BG$6:$CU$6,0)+56,0) -> 0.14 | G13: =+VLOOKUP(A13,'[4]B2B Red'!$C:$FG,MATCH($A$3,'[4]B2B Red'!$BG$6:$CU$6,0)+57,0) -> 0.18 | H13: =+F13 -> 0.14 | I13: =+G13 -> 0.18 | K13: =+VLOOKUP(A13,'[4]B2B Red'!$C:$FG,MATCH($A$3,'[4]B2B Red'!$BG$6:$CU$6,0)+58,0)+4% -> 0.26 | N13: =IF((F13-VLOOKUP($A13,[2]Citroën!$A:$L,COLUMNS([2]Citroën!$A$9:$F$9),0))*100=0,"ISO",(F13-VLOOKUP($A13,[2]Citroën!$A:$L,COLUMNS([2]Citroën!$A$9:$F$9),0))*100) -> 2 | O13: =IF((G13-VLOOKUP($A13,[2]Citroën!$A:$L,COLUMNS([2]Citroën!$A$9:$G$9),0))*100=0,"ISO",(G13-VLOOKUP($A13,[2]Citroën!$A:$L,COLUMNS([2]Citroën!$A$9:$G$9),0))*100) -> 2 | P13: =IF((K13-VLOOKUP($A13,[2]Citroën!$A:$L,COLUMNS([2]Citroën!$A$9:$K$9),0))*100=0,"ISO",(K13-VLOOKUP($A13,[2]Citroën!$A:$L,COLUMNS([2]Citroën!$A$9:$K$9),0))*100) -> 2
A14: K9 VU | E14: Stellantis | F14: =+F13-F15 -> 0.095 | G14: =+G13-G15 -> 0.13 | H14: =+H13-H15 -> 0.085 | I14: =+I13-I15 -> 0.12 | K14: =+K13-K15 -> 0.18 | N14: =+IF((ROUND(F14-HLOOKUP(F$7,[2]Citroën!$F$7:$G$86,MATCH($A13,[2]Citroën!$A$7:$A$86,0)+1,0),3))*100=0,"ISO",(F14-HLOOKUP(F$7,[2]Citroën!$F$7:$G$86,MATCH($A13,[2]Citroën!$A$7:$A$86,0)+1,0))*100) -> 2 | O14: =+IF((ROUND(G14-HLOOKUP(G$7,[2]Citroën!$F$7:$G$86,MATCH($A13,[2]Citroën!$A$7:$A$86,0)+1,0),3))*100=0,"ISO",(G14-HLOOKUP(G$7,[2]Citroën!$F$7:$G$86,MATCH($A13,[2]Citroën!$A$7:$A$86,0)+1,0))*100) -> 2 | P14: =IF((ROUND(K14-HLOOKUP(K$7,[2]Citroën!$K$7:$L$86,MATCH($A13,[2]Citroën!$A$7:$A$86,0)+1,0),3))*100=0,"ISO",(K14-HLOOKUP(K$7,[2]Citroën!$K$7:$L$86,MATCH($A13,[2]Citroën!$A$7:$A$86,0)+1,0))*100) -> 1
